Workbook

Sheet 物件データ
A1: 物件データ（入力シートから抽出・売却決済日順）
A2: 青字＝入力シートからの転記値、黒字＝数式。売却決済日が空欄の物件は末尾（未売却）
A4: No | B4: 物件種別 | C4: 物件名 | D4: 仕入決済日 | E4: 売却契約日 | F4: 売却決済日 | G4: 販売価格(円) | H4: 仕入原価(円) | I4: 商品化原価(円) | J4: 期 | K4: 状態 | L4: 集計対象 | M4: 粗利(円) | N4: 粗利率 | O4: 保有日数 | P4: 価格帯 | Q4: 入力シート行 | R4: データ注記
A5: 12 | B5: MSリフォーム再販 | C5: マンション第一多摩川苑 | D5: 44609 | E5: 44823 | F5: 44875 | G5: 25900000 | I5: 0 | J5: =IF(F5="","",IFERROR(INDEX(設定!$A$8:$A$15,MATCH(F5,設定!$B$8:$B$15,1)),"対象外")) -> 10期 | K5: =IF(F5="","未売却",IF(F5<=設定!$B$3,"実績","予定")) -> 実績 | L5: =IF(F5="",0,IF(OR(設定!$B$4="全て",K5="実績"),1,0)) -> 1 | M5: =IF(OR(G5="",H5=""),"",G5-H5-I5) | N5: =IF(M5="","",M5/G5) | O5: =IF(OR(D5="",F5=""),"",F5-D5) -> 266 | P5: =IF(G5="","",IF(INT(G5/設定!$B$5)*設定!$B$5>=100000000,TEXT(INT(G5/設定!$B$5)*設定!$B$5/100000000,"0.0")&"億",TEXT(INT(G5/設定!$B$5)*設定!$B$5/10000,"#,##0")&"万")&"〜") -> 0万〜 | Q5: 16 | R5: 仕入原価未入力→粗利対象外
A6: 19 | B6: 新築戸建 | C6: 東大泉新築Ａ | D6: 44693 | E6: 44819 | F6: 44889 | G6: 59800000 | I6: 13000000 | J6: =IF(F6="","",IFERROR(INDEX(設定!$A$8:$A$15,MATCH(F6,設定!$B$8:$B$15,1)),"対象外")) -> 10期 | K6: =IF(F6="","未売却",IF(F6<=設定!$B$3,"実績","予定")) -> 実績 | L6: =IF(F6="",0,IF(OR(設定!$B$4="全て",K6="実績"),1,0)) -> 1 | M6: =IF(OR(G6="",H6=""),"",G6-H6-I6) | N6: =IF(M6="","",M6/G6) | O6: =IF(OR(D6="",F6=""),"",F6-D6) -> 196 | P6: =IF(G6="","",IF(INT(G6/設定!$B$5)*設定!$B$5>=100000000,TEXT(INT(G6/設定!$B$5)*設定!$B$5/100000000,"0.0")&"億",TEXT(INT(G6/設定!$B$5)*設定!$B$5/10000,"#,##0")&"万")&"〜") -> 5,000万〜 | Q6: 23 | R6: 仕入原価未入力→粗利対象外
A7: 22 | B7: MSリフォーム再販 | C7: コートヒルズ高輪 | D7: 44728 | E7: 44858 | F7: 44910 | G7: 69900000 | I7: 0 | J7: =IF(F7="","",IFERROR(INDEX(設定!$A$8:$A$15,MATCH(F7,設定!$B$8:$B$15,1)),"対象外")) -> 10期 | K7: =IF(F7="","未売却",IF(F7<=設定!$B$3,"実績","予定")) -> 実績 | L7: =IF(F7="",0,IF(OR(設定!$B$4="全て",K7="実績"),1,0)) -> 1 | M7: =IF(OR(G7="",H7=""),"",G7-H7-I7) | N7: =IF(M7="","",M7/G7) | O7: =IF(OR(D7="",F7=""),"",F7-D7) -> 182 | P7: =IF(G7="","",IF(INT(G7/設定!$B$5)*設定!$B$5>=100000000,TEXT(INT(G7/設定!$B$5)*設定!$B$5/100000000,"0.0")&"億",TEXT(INT(G7/設定!$B$5)*設定!$B$5/10000,"#,##0")&"万")&"〜") -> 5,000万〜 | Q7: 26 | R7: 仕入原価未入力→粗利対象外
A8: 29 | B8: 戸建リフォーム再販 | C8: 柿の木坂2丁目中古戸建 | D8: 44799 | E8: 44878 | F8: 44914 | G8: 67800000 | I8: 9000000 | J8: =IF(F8="","",IFERROR(INDEX(設定!$A$8:$A$15,MATCH(F8,設定!$B$8:$B$15,1)),"対象外")) -> 10期 | K8: =IF(F8="","未売却",IF(F8<=設定!$B$3,"実績","予定")) -> 実績 | L8: =IF(F8="",0,IF(OR(設定!$B$4="全て",K8="実績"),1,0)) -> 1 | M8: =IF(OR(G8="",H8=""),"",G8-H8-I8) | N8: =IF(M8="","",M8/G8) | O8: =IF(OR(D8="",F8=""),"",F8-D8) -> 115 | P8: =IF(G8="","",IF(INT(G8/設定!$B$5)*設定!$B$5>=100000000,TEXT(INT(G8/設定!$B$5)*設定!$B$5/100000000,"0.0")&"億",TEXT(INT(G8/設定!$B$5)*設定!$B$5/10000,"#,##0")&"万")&"〜") -> 5,000万〜 | Q8: 33 | R8: 仕入原価未入力→粗利対象外
A9: 39 | B9: MSリフォーム再販 | C9: フィールファイン | D9: 44862 | E9: 44834 | F9: 44915 | G9: 109000000 | I9: 0 | J9: =IF(F9="","",IFERROR(INDEX(設定!$A$8:$A$15,MATCH(F9,設定!$B$8:$B$15,1)),"対象外")) -> 10期 | K9: =IF(F9="","未売却",IF(F9<=設定!$B$3,"実績","予定")) -> 実績 | L9: =IF(F9="",0,IF(OR(設定!$B$4="全て",K9="実績"),1,0)) -> 1 | M9: =IF(OR(G9="",H9=""),"",G9-H9-I9) | N9: =IF(M9="","",M9/G9) | O9: =IF(OR(D9="",F9=""),"",F9-D9) -> 53 | P9: =IF(G9="","",IF(INT(G9/設定!$B$5)*設定!$B$5>=100000000,TEXT(INT(G9/設定!$B$5)*設定!$B$5/100000000,"0.0")&"億",TEXT(INT(G9/設定!$B$5)*設定!$B$5/10000,"#,##0")&"万")&"〜") -> 1.0億〜 | Q9: 43 | R9: 仕入原価未入力→粗利対象外
A10: 20 | B10: 新築戸建 | C10: 東大泉新築Ｂ | D10: 44693 | E10: 44885 | F10: 44921 | G10: 59800000 | I10: 13000000 | J10: =IF(F10="","",IFERROR(INDEX(設定!$A$8:$A$15,MATCH(F10,設定!$B$8:$B$15,1)),"対象外")) -> 10期 | K10: =IF(F10="","未売却",IF(F10<=設定!$B$3,"実績","予定")) -> 実績 | L10: =IF(F10="",0,IF(OR(設定!$B$4="全て",K10="実績"),1,0)) -> 1 | M10: =IF(OR(G10="",H10=""),"",G10-H10-I10) | N10: =IF(M10="","",M10/G10) | O10: =IF(OR(D10="",F10=""),"",F10-D10) -> 228 | P10: =IF(G10="","",IF(INT(G10/設定!$B$5)*設定!$B$5>=100000000,TEXT(INT(G10/設定!$B$5)*設定!$B$5/100000000,"0.0")&"億",TEXT(INT(G10/設定!$B$5)*設定!$B$5/10000,"#,##0")&"万")&"〜") -> 5,000万〜 | Q10: 24 | R10: 仕入原価未入力→粗利対象外
A11: 2 | B11: 新築戸建 | C11: 立野新築Ｂ号棟 | D11: 44413 | E11: 44903 | F11: 44922 | G11: 47800000 | I11: 22000000 | J11: =IF(F11="","",IFERROR(INDEX(設定!$A$8:$A$15,MATCH(F11,設定!$B$8:$B$15,1)),"対象外")) -> 10期 | K11: =IF(F11="","未売却",IF(F11<=設定!$B$3,"実績","予定")) -> 実績 | L11: =IF(F11="",0,IF(OR(設定!$B$4="全て",K11="実績"),1,0)) -> 1 | M11: =IF(OR(G11="",H11=""),"",G11-H11-I11) | N11: =IF(M11="","",M11/G11) | O11: =IF(OR(D11="",F11=""),"",F11-D11) -> 509 | P11: =IF(G11="","",IF(INT(G11/設定!$B$5)*設定!$B$5>=100000000,TEXT(INT(G11/設定!$B$5)*設定!$B$5/100000000,"0.0")&"億",TEXT(INT(G11/設定!$B$5)*設定!$B$5/10000,"#,##0")&"万")&"〜") -> 0万〜 | Q11: 6 | R11: 仕入原価未入力→粗利対象外
A12: 18 | B12: 戸建リフォーム再販 | C12: 墨田区八広中古戸建 | D12: 44620 | E12: 44822 | F12: 44932 | G12: 92800000 | I12: 0 | J12: =IF(F12="","",IFERROR(INDEX(設定!$A$8:$A$15,MATCH(F12,設定!$B$8:$B$15,1)),"対象外")) -> 10期 | K12: =IF(F12="","未売却",IF(F12<=設定!$B$3,"実績","予定")) -> 実績 | L12: =IF(F12="",0,IF(OR(設定!$B$4="全て",K12="実績"),1,0)) -> 1 | M12: =IF(OR(G12="",H12=""),"",G12-H12-I12) | N12: =IF(M12="","",M12/G12) | O12: =IF(OR(D12="",F12=""),"",F12-D12) -> 312 | P12: =IF(G12="","",IF(INT(G12/設定!$B$5)*設定!$B$5>=100000000,TEXT(INT(G12/設定!$B$5)*設定!$B$5/100000000,"0.0")&"億",TEXT(INT(G12/設定!$B$5)*設定!$B$5/10000,"#,##0")&"万")&"〜") -> 5,000万〜 | Q12: 22 | R12: 仕入原価未入力→粗利対象外
A13: 15 | B13: 新築戸建 | C13: 中川新築Ｂ | D13: 44681 | E13: 44794 | F13: 44953 | G13: 39900000 | I13: 14000000 | J13: =IF(F13="","",IFERROR(INDEX(設定!$A$8:$A$15,MATCH(F13,設定!$B$8:$B$15,1)),"対象外")) -> 10期 | K13: =IF(F13="","未売却",IF(F13<=設定!$B$3,"実績","予定")) -> 実績 | L13: =IF(F13="",0,IF(OR(設定!$B$4="全て",K13="実績"),1,0)) -> 1 | M13: =IF(OR(G13="",H13=""),"",G13-H13-I13) | N13: =IF(M13="","",M13/G13) | O13: =IF(OR(D13="",F13=""),"",F13-D13) -> 272 | P13: =IF(G13="","",IF(INT(G13/設定!$B$5)*設定!$B$5>=100000000,TEXT(INT(G13/設定!$B$5)*設定!$B$5/100000000,"0.0")&"億",TEXT(INT(G13/設定!$B$5)*設定!$B$5/10000,"#,##0")&"万")&"〜") -> 0万〜 | Q13: 19 | R13: 仕入原価未入力→粗利対象外
A14: 36 | B14: 戸建リフォーム再販 | C14: 粕谷中古戸建 | D14: 44834 | E14: 44909 | F14: 44963 | G14: 58800000 | I14: 5000000 | J14: =IF(F14="","",IFERROR(INDEX(設定!$A$8:$A$15,MATCH(F14,設定!$B$8:$B$15,1)),"対象外")) -> 10期 | K14: =IF(F14="","未売却",IF(F14<=設定!$B$3,"実績","予定")) -> 実績 | L14: =IF(F14="",0,IF(OR(設定!$B$4="全て",K14="実績"),1,0)) -> 1 | M14: =IF(OR(G14="",H14=""),"",G14-H14-I14) | N14: =IF(M14="","",M14/G14) | O14: =IF(OR(D14="",F14=""),"",F14-D14) -> 129 | P14: =IF(G14="","",IF(INT(G14/設定!$B$5)*設定!$B$5>=100000000,TEXT(INT(G14/設定!$B$5)*設定!$B$5/100000000,"0.0")&"億",TEXT(INT(G14/設定!$B$5)*設定!$B$5/10000,"#,##0")&"万")&"〜") -> 5,000万〜 | Q14: 40 | R14: 仕入原価未入力→粗利対象外
A15: 14 | B15: 新築戸建 | C15: 中川新築Ａ | D15: 44681 | E15: 44915 | F15: 44970 | G15: 39900000 | I15: 14000000 | J15: =IF(F15="","",IFERROR(INDEX(設定!$A$8:$A$15,MATCH(F15,設定!$B$8:$B$15,1)),"対象外")) -> 10期 | K15: =IF(F15="","未売却",IF(F15<=設定!$B$3,"実績","予定")) -> 実績 | L15: =IF(F15="",0,IF(OR(設定!$B$4="全て",K15="実績"),1,0)) -> 1 | M15: =IF(OR(G15="",H15=""),"",G15-H15-I15) | N15: =IF(M15="","",M15/G15) | O15: =IF(OR(D15="",F15=""),"",F15-D15) -> 289 | P15: =IF(G15="","",IF(INT(G15/設定!$B$5)*設定!$B$5>=100000000,TEXT(INT(G15/設定!$B$5)*設定!$B$5/100000000,"0.0")&"億",TEXT(INT(G15/設定!$B$5)*設定!$B$5/10000,"#,##0")&"万")&"〜") -> 0万〜 | Q15: 18 | R15: 仕入原価未入力→粗利対象外
A16: 16 | B16: 新築戸建 | C16: 中川新築Ｃ | D16: 44681 | E16: 44898 | F16: 44970 | G16: 39900000 | I16: 14000000 | J16: =IF(F16="","",IFERROR(INDEX(設定!$A$8:$A$15,MATCH(F16,設定!$B$8:$B$15,1)),"対象外")) -> 10期 | K16: =IF(F16="","未売却",IF(F16<=設定!$B$3,"実績","予定")) -> 実績 | L16: =IF(F16="",0,IF(OR(設定!$B$4="全て",K16="実績"),1,0)) -> 1 | M16: =IF(OR(G16="",H16=""),"",G16-H16-I16) | N16: =IF(M16="","",M16/G16) | O16: =IF(OR(D16="",F16=""),"",F16-D16) -> 289 | P16: =IF(G16="","",IF(INT(G16/設定!$B$5)*設定!$B$5>=100000000,TEXT(INT(G16/設定!$B$5)*設定!$B$5/100000000,"0.0")&"億",TEXT(INT(G16/設定!$B$5)*設定!$B$5/10000,"#,##0")&"万")&"〜") -> 0万〜 | Q16: 20 | R16: 仕入原価未入力→粗利対象外
A17: 7 | B17: 新築戸建 | C17: 世田谷区池尻新築戸建 | D17: 44540 | E17: 44946 | F17: 44985 | G17: 126500000 | I17: 31691326 | J17: =IF(F17="","",IFERROR(INDEX(設定!$A$8:$A$15,MATCH(F17,設定!$B$8:$B$15,1)),"対象外")) -> 10期 | K17: =IF(F17="","未売却",IF(F17<=設定!$B$3,"実績","予定")) -> 実績 | L17: =IF(F17="",0,IF(OR(設定!$B$4="全て",K17="実績"),1,0)) -> 1 | M17: =IF(OR(G17="",H17=""),"",G17-H17-I17) | N17: =IF(M17="","",M17/G17) | O17: =IF(OR(D17="",F17=""),"",F17-D17) -> 445 | P17: =IF(G17="","",IF(INT(G17/設定!$B$5)*設定!$B$5>=100000000,TEXT(INT(G17/設定!$B$5)*設定!$B$5/100000000,"0.0")&"億",TEXT(INT(G17/設定!$B$5)*設定!$B$5/10000,"#,##0")&"万")&"〜") -> 1.0億〜 | Q17: 11 | R17: 仕入原価未入力→粗利対象外
A18: 59 | B18: MSリフォーム再販 | C18: 原宿インペリアルハイツ | E18: 44975 | F18: 44985 | G18: 34800000 | I18: 0 | J18: =IF(F18="","",IFERROR(INDEX(設定!$A$8:$A$15,MATCH(F18,設定!$B$8:$B$15,1)),"対象外")) -> 10期 | K18: =IF(F18="","未売却",IF(F18<=設定!$B$3,"実績","予定")) -> 実績 | L18: =IF(F18="",0,IF(OR(設定!$B$4="全て",K18="実績"),1,0)) -> 1 | M18: =IF(OR(G18="",H18=""),"",G18-H18-I18) | N18: =IF(M18="","",M18/G18) | O18: =IF(OR(D18="",F18=""),"",F18-D18) | P18: =IF(G18="","",IF(INT(G18/設定!$B$5)*設定!$B$5>=100000000,TEXT(INT(G18/設定!$B$5)*設定!$B$5/100000000,"0.0")&"億",TEXT(INT(G18/設定!$B$5)*設定!$B$5/10000,"#,##0")&"万")&"〜") -> 0万〜 | Q18: 63 | R18: 仕入決済日が空欄→保有日数算出不可 / 仕入原価未入力→粗利対象外
A19: 10 | B19: MSリフォーム再販 | C19: クレイシア戸越公園 | D19: 44558 | E19: 44954 | F19: 44991 | G19: 42000000 | I19: 0 | J19: =IF(F19="","",IFERROR(INDEX(設定!$A$8:$A$15,MATCH(F19,設定!$B$8:$B$15,1)),"対象外")) -> 10期 | K19: =IF(F19="","未売却",IF(F19<=設定!$B$3,"実績","予定")) -> 実績 | L19: =IF(F19="",0,IF(OR(設定!$B$4="全て",K19="実績"),1,0)) -> 1 | M19: =IF(OR(G19="",H19=""),"",G19-H19-I19) | N19: =IF(M19="","",M19/G19) | O19: =IF(OR(D19="",F19=""),"",F19-D19) -> 433 | P19: =IF(G19="","",IF(INT(G19/設定!$B$5)*設定!$B$5>=100000000,TEXT(INT(G19/設定!$B$5)*設定!$B$5/100000000,"0.0")&"億",TEXT(INT(G19/設定!$B$5)*設定!$B$5/10000,"#,##0")&"万")&"〜") -> 0万〜 | Q19: 14 | R19: 仕入原価未入力→粗利対象外
A20: 4 | B20: 新築戸建 | C20: 大田区南久が原新築Ａ | D20: 44644 | E20: 44955 | F20: 45008 | G20: 59500000 | I20: 18000000 | J20: =IF(F20="","",IFERROR(INDEX(設定!$A$8:$A$15,MATCH(F20,設定!$B$8:$B$15,1)),"対象外")) -> 10期 | K20: =IF(F20="","未売却",IF(F20<=設定!$B$3,"実績","予定")) -> 実績 | L20: =IF(F20="",0,IF(OR(設定!$B$4="全て",K20="実績"),1,0)) -> 1 | M20: =IF(OR(G20="",H20=""),"",G20-H20-I20) | N20: =IF(M20="","",M20/G20) | O20: =IF(OR(D20="",F20=""),"",F20-D20) -> 364 | P20: =IF(G20="","",IF(INT(G20/設定!$B$5)*設定!$B$5>=100000000,TEXT(INT(G20/設定!$B$5)*設定!$B$5/100000000,"0.0")&"億",TEXT(INT(G20/設定!$B$5)*設定!$B$5/10000,"#,##0")&"万")&"〜") -> 5,000万〜 | Q20: 8 | R20: 仕入原価未入力→粗利対象外
A21: 8 | B21: 新築戸建 | C21: 東雪谷新築戸建A | D21: 44681 | E21: 44834 | F21: 45012 | G21: 48800000 | I21: 13100000 | J21: =IF(F21="","",IFERROR(INDEX(設定!$A$8:$A$15,MATCH(F21,設定!$B$8:$B$15,1)),"対象外")) -> 10期 | K21: =IF(F21="","未売却",IF(F21<=設定!$B$3,"実績","予定")) -> 実績 | L21: =IF(F21="",0,IF(OR(設定!$B$4="全て",K21="実績"),1,0)) -> 1 | M21: =IF(OR(G21="",H21=""),"",G21-H21-I21) | N21: =IF(M21="","",M21/G21) | O21: =IF(OR(D21="",F21=""),"",F21-D21) -> 331 | P21: =IF(G21="","",IF(INT(G21/設定!$B$5)*設定!$B$5>=100000000,TEXT(INT(G21/設定!$B$5)*設定!$B$5/100000000,"0.0")&"億",TEXT(INT(G21/設定!$B$5)*設定!$B$5/10000,"#,##0")&"万")&"〜") -> 0万〜 | Q21: 12 | R21: 仕入原価未入力→粗利対象外
A22: 35 | B22: 条件なし土地 | C22: 中央5丁目ＡＰ用地 | D22: 44830 | E22: 44972 | F22: 45015 | G22: 81000000 | I22: 3000000 | J22: =IF(F22="","",IFERROR(INDEX(設定!$A$8:$A$15,MATCH(F22,設定!$B$8:$B$15,1)),"対象外")) -> 10期 | K22: =IF(F22="","未売却",IF(F22<=設定!$B$3,"実績","予定")) -> 実績 | L22: =IF(F22="",0,IF(OR(設定!$B$4="全て",K22="実績"),1,0)) -> 1 | M22: =IF(OR(G22="",H22=""),"",G22-H22-I22) | N22: =IF(M22="","",M22/G22) | O22: =IF(OR(D22="",F22=""),"",F22-D22) -> 185 | P22: =IF(G22="","",IF(INT(G22/設定!$B$5)*設定!$B$5>=100000000,TEXT(INT(G22/設定!$B$5)*設定!$B$5/100000000,"0.0")&"億",TEXT(INT(G22/設定!$B$5)*設定!$B$5/10000,"#,##0")&"万")&"〜") -> 5,000万〜 | Q22: 39 | R22: 仕入原価未入力→粗利対象外
A23: 44 | B23: 条件なし土地 | C23: 三軒茶屋土地 | D23: 44985 | E23: 45008 | F23: 45058 | G23: 138000000 | H23: 107214000 | I23: 2000000 | J23: =IF(F23="","",IFERROR(INDEX(設定!$A$8:$A$15,MATCH(F23,設定!$B$8:$B$15,1)),"対象外")) -> 10期 | K23: =IF(F23="","未売却",IF(F23<=設定!$B$3,"実績","予定")) -> 実績 | L23: =IF(F23="",0,IF(OR(設定!$B$4="全て",K23="実績"),1,0)) -> 1 | M23: =IF(OR(G23="",H23=""),"",G23-H23-I23) -> 28786000 | N23: =IF(M23="","",M23/G23) -> 0.2085942 | O23: =IF(OR(D23="",F23=""),"",F23-D23) -> 73 | P23: =IF(G23="","",IF(INT(G23/設定!$B$5)*設定!$B$5>=100000000,TEXT(INT(G23/設定!$B$5)*設定!$B$5/100000000,"0.0")&"億",TEXT(INT(G23/設定!$B$5)*設定!$B$5/10000,"#,##0")&"万")&"〜") -> 1.0億〜 | Q23: 48
A24: 43 | B24: 戸建リフォーム再販 | C24: 奥沢中古戸建 | D24: 44921 | E24: 44980 | F24: 45072 | G24: 83800000 | H24: 64458000 | I24: 9000000 | J24: =IF(F24="","",IFERROR(INDEX(設定!$A$8:$A$15,MATCH(F24,設定!$B$8:$B$15,1)),"対象外")) -> 10期 | K24: =IF(F24="","未売却",IF(F24<=設定!$B$3,"実績","予定")) -> 実績 | L24: =IF(F24="",0,IF(OR(設定!$B$4="全て",K24="実績"),1,0)) -> 1 | M24: =IF(OR(G24="",H24=""),"",G24-H24-I24) -> 10342000 | N24: =IF(M24="","",M24/G24) -> 0.12341289 | O24: =IF(OR(D24="",F24=""),"",F24-D24) -> 151 | P24: =IF(G24="","",IF(INT(G24/設定!$B$5)*設定!$B$5>=100000000,TEXT(INT(G24/設定!$B$5)*設定!$B$5/100000000,"0.0")&"億",TEXT(INT(G24/設定!$B$5)*設定!$B$5/10000,"#,##0")&"万")&"〜") -> 5,000万〜 | Q24: 47
A25: 24 | B25: 新築戸建 | C25: 荏原6丁目Ｂ | D25: 44736 | E25: 45018 | F25: 45075 | G25: 64800000 | I25: 0 | J25: =IF(F25="","",IFERROR(INDEX(設定!$A$8:$A$15,MATCH(F25,設定!$B$8:$B$15,1)),"対象外")) -> 10期 | K25: =IF(F25="","未売却",IF(F25<=設定!$B$3,"実績","予定")) -> 実績 | L25: =IF(F25="",0,IF(OR(設定!$B$4="全て",K25="実績"),1,0)) -> 1 | M25: =IF(OR(G25="",H25=""),"",G25-H25-I25) | N25: =IF(M25="","",M25/G25) | O25: =IF(OR(D25="",F25=""),"",F25-D25) -> 339 | P25: =IF(G25="","",IF(INT(G25/設定!$B$5)*設定!$B$5>=100000000,TEXT(INT(G25/設定!$B$5)*設定!$B$5/100000000,"0.0")&"億",TEXT(INT(G25/設定!$B$5)*設定!$B$5/10000,"#,##0")&"万")&"〜") -> 5,000万〜 | Q25: 28 | R25: 仕入原価未入力→粗利対象外
A26: 25 | B26: 新築戸建 | C26: 上小田中1丁目新築Ａ | D26: 44782 | E26: 44905 | F26: 45075 | G26: 48800000 | I26: 16000000 | J26: =IF(F26="","",IFERROR(INDEX(設定!$A$8:$A$15,MATCH(F26,設定!$B$8:$B$15,1)),"対象外")) -> 10期 | K26: =IF(F26="","未売却",IF(F26<=設定!$B$3,"実績","予定")) -> 実績 | L26: =IF(F26="",0,IF(OR(設定!$B$4="全て",K26="実績"),1,0)) -> 1 | M26: =IF(OR(G26="",H26=""),"",G26-H26-I26) | N26: =IF(M26="","",M26/G26) | O26: =IF(OR(D26="",F26=""),"",F26-D26) -> 293 | P26: =IF(G26="","",IF(INT(G26/設定!$B$5)*設定!$B$5>=100000000,TEXT(INT(G26/設定!$B$5)*設定!$B$5/100000000,"0.0")&"億",TEXT(INT(G26/設定!$B$5)*設定!$B$5/10000,"#,##0")&"万")&"〜") -> 0万〜 | Q26: 29 | R26: 仕入原価未入力→粗利対象外
A27: 23 | B27: 新築戸建 | C27: 荏原6丁目Ａ | D27: 44736 | E27: 45031 | F27: 45076 | G27: 64800000 | I27: 0 | J27: =IF(F27="","",IFERROR(INDEX(設定!$A$8:$A$15,MATCH(F27,設定!$B$8:$B$15,1)),"対象外")) -> 10期 | K27: =IF(F27="","未売却",IF(F27<=設定!$B$3,"実績","予定")) -> 実績 | L27: =IF(F27="",0,IF(OR(設定!$B$4="全て",K27="実績"),1,0)) -> 1 | M27: =IF(OR(G27="",H27=""),"",G27-H27-I27) | N27: =IF(M27="","",M27/G27) | O27: =IF(OR(D27="",F27=""),"",F27-D27) -> 340 | P27: =IF(G27="","",IF(INT(G27/設定!$B$5)*設定!$B$5>=100000000,TEXT(INT(G27/設定!$B$5)*設定!$B$5/100000000,"0.0")&"億",TEXT(INT(G27/設定!$B$5)*設定!$B$5/10000,"#,##0")&"万")&"〜") -> 5,000万〜 | Q27: 27 | R27: 仕入原価未入力→粗利対象外
A28: 26 | B28: 新築戸建 | C28: 上小田中1丁目新築戸建Ｂ | D28: 44782 | E28: 44870 | F28: 45082 | G28: 51800000 | I28: 16250000 | J28: =IF(F28="","",IFERROR(INDEX(設定!$A$8:$A$15,MATCH(F28,設定!$B$8:$B$15,1)),"対象外")) -> 10期 | K28: =IF(F28="","未売却",IF(F28<=設定!$B$3,"実績","予定")) -> 実績 | L28: =IF(F28="",0,IF(OR(設定!$B$4="全て",K28="実績"),1,0)) -> 1 | M28: =IF(OR(G28="",H28=""),"",G28-H28-I28) | N28: =IF(M28="","",M28/G28) | O28: =IF(OR(D28="",F28=""),"",F28-D28) -> 300 | P28: =IF(G28="","",IF(INT(G28/設定!$B$5)*設定!$B$5>=100000000,TEXT(INT(G28/設定!$B$5)*設定!$B$5/100000000,"0.0")&"億",TEXT(INT(G28/設定!$B$5)*設定!$B$5/10000,"#,##0")&"万")&"〜") -> 5,000万〜 | Q28: 30 | R28: 仕入原価未入力→粗利対象外
A29: 31 | B29: 条件付き土地 | C29: 若林4丁目条件付土地 | D29: 44819 | E29: 45046 | F29: 45097 | G29: 47800000 | I29: 0 | J29: =IF(F29="","",IFERROR(INDEX(設定!$A$8:$A$15,MATCH(F29,設定!$B$8:$B$15,1)),"対象外")) -> 10期 | K29: =IF(F29="","未売却",IF(F29<=設定!$B$3,"実績","予定")) -> 実績 | L29: =IF(F29="",0,IF(OR(設定!$B$4="全て",K29="実績"),1,0)) -> 1 | M29: =IF(OR(G29="",H29=""),"",G29-H29-I29) | N29: =IF(M29="","",M29/G29) | O29: =IF(OR(D29="",F29=""),"",F29-D29) -> 278 | P29: =IF(G29="","",IF(INT(G29/設定!$B$5)*設定!$B$5>=100000000,TEXT(INT(G29/設定!$B$5)*設定!$B$5/100000000,"0.0")&"億",TEXT(INT(G29/設定!$B$5)*設定!$B$5/10000,"#,##0")&"万")&"〜") -> 0万〜 | Q29: 35 | R29: 仕入原価未入力→粗利対象外
A30: 11 | B30: 新築戸建 | C30: 苅宿新築戸建 | D30: 44830 | E30: 44940 | F30: 45107 | G30: 64900000 | I30: 20000000 | J30: =IF(F30="","",IFERROR(INDEX(設定!$A$8:$A$15,MATCH(F30,設定!$B$8:$B$15,1)),"対象外")) -> 10期 | K30: =IF(F30="","未売却",IF(F30<=設定!$B$3,"実績","予定")) -> 実績 | L30: =IF(F30="",0,IF(OR(設定!$B$4="全て",K30="実績"),1,0)) -> 1 | M30: =IF(OR(G30="",H30=""),"",G30-H30-I30) | N30: =IF(M30="","",M30/G30) | O30: =IF(OR(D30="",F30=""),"",F30-D30) -> 277 | P30: =IF(G30="","",IF(INT(G30/設定!$B$5)*設定!$B$5>=100000000,TEXT(INT(G30/設定!$B$5)*設定!$B$5/100000000,"0.0")&"億",TEXT(INT(G30/設定!$B$5)*設定!$B$5/10000,"#,##0")&"万")&"〜") -> 5,000万〜 | Q30: 15 | R30: 仕入原価未入力→粗利対象外
A31: 32 | B31: 新築戸建 | C31: 宮内3丁目新築戸建Ａ | D31: 44830 | E31: 44998 | F31: 45107 | G31: 46800000 | I31: 16750000 | J31: =IF(F31="","",IFERROR(INDEX(設定!$A$8:$A$15,MATCH(F31,設定!$B$8:$B$15,1)),"対象外")) -> 10期 | K31: =IF(F31="","未売却",IF(F31<=設定!$B$3,"実績","予定")) -> 実績 | L31: =IF(F31="",0,IF(OR(設定!$B$4="全て",K31="実績"),1,0)) -> 1 | M31: =IF(OR(G31="",H31=""),"",G31-H31-I31) | N31: =IF(M31="","",M31/G31) | O31: =IF(OR(D31="",F31=""),"",F31-D31) -> 277 | P31: =IF(G31="","",IF(INT(G31/設定!$B$5)*設定!$B$5>=100000000,TEXT(INT(G31/設定!$B$5)*設定!$B$5/100000000,"0.0")&"億",TEXT(INT(G31/設定!$B$5)*設定!$B$5/10000,"#,##0")&"万")&"〜") -> 0万〜 | Q31: 36 | R31: 仕入原価未入力→粗利対象外
A32: 33 | B32: 新築戸建 | C32: 宮内3丁目新築戸建Ｂ | D32: 44830 | E32: 44988 | F32: 45107 | G32: 45400000 | I32: 16750000 | J32: =IF(F32="","",IFERROR(INDEX(設定!$A$8:$A$15,MATCH(F32,設定!$B$8:$B$15,1)),"対象外")) -> 10期 | K32: =IF(F32="","未売却",IF(F32<=設定!$B$3,"実績","予定")) -> 実績 | L32: =IF(F32="",0,IF(OR(設定!$B$4="全て",K32="実績"),1,0)) -> 1 | M32: =IF(OR(G32="",H32=""),"",G32-H32-I32) | N32: =IF(M32="","",M32/G32) | O32: =IF(OR(D32="",F32=""),"",F32-D32) -> 277 | P32: =IF(G32="","",IF(INT(G32/設定!$B$5)*設定!$B$5>=100000000,TEXT(INT(G32/設定!$B$5)*設定!$B$5/100000000,"0.0")&"億",TEXT(INT(G32/設定!$B$5)*設定!$B$5/10000,"#,##0")&"万")&"〜") -> 0万〜 | Q32: 37 | R32: 仕入原価未入力→粗利対象外
A33: 34 | B33: 新築戸建 | C33: 宮内3丁目新築戸建Ｃ | D33: 44830 | E33: 44920 | F33: 45107 | G33: 48800000 | I33: 16750000 | J33: =IF(F33="","",IFERROR(INDEX(設定!$A$8:$A$15,MATCH(F33,設定!$B$8:$B$15,1)),"対象外")) -> 10期 | K33: =IF(F33="","未売却",IF(F33<=設定!$B$3,"実績","予定")) -> 実績 | L33: =IF(F33="",0,IF(OR(設定!$B$4="全て",K33="実績"),1,0)) -> 1 | M33: =IF(OR(G33="",H33=""),"",G33-H33-I33) | N33: =IF(M33="","",M33/G33) | O33: =IF(OR(D33="",F33=""),"",F33-D33) -> 277 | P33: =IF(G33="","",IF(INT(G33/設定!$B$5)*設定!$B$5>=100000000,TEXT(INT(G33/設定!$B$5)*設定!$B$5/100000000,"0.0")&"億",TEXT(INT(G33/設定!$B$5)*設定!$B$5/10000,"#,##0")&"万")&"〜") -> 0万〜 | Q33: 38 | R33: 仕入原価未入力→粗利対象外
A34: 42 | B34: 条件付き土地 | C34: 目黒本町5丁目条件付き土地 | D34: 44957 | E34: 45077 | F34: 45107 | G34: 59900000 | H34: 50366400 | I34: 500000 | J34: =IF(F34="","",IFERROR(INDEX(設定!$A$8:$A$15,MATCH(F34,設定!$B$8:$B$15,1)),"対象外")) -> 10期 | K34: =IF(F34="","未売却",IF(F34<=設定!$B$3,"実績","予定")) -> 実績 | L34: =IF(F34="",0,IF(OR(設定!$B$4="全て",K34="実績"),1,0)) -> 1 | M34: =IF(OR(G34="",H34=""),"",G34-H34-I34) -> 9033600 | N34: =IF(M34="","",M34/G34) -> 0.15081135 | O34: =IF(OR(D34="",F34=""),"",F34-D34) -> 150 | P34: =IF(G34="","",IF(INT(G34/設定!$B$5)*設定!$B$5>=100000000,TEXT(INT(G34/設定!$B$5)*設定!$B$5/100000000,"0.0")&"億",TEXT(INT(G34/設定!$B$5)*設定!$B$5/10000,"#,##0")&"万")&"〜") -> 5,000万〜 | Q34: 46
A35: 62 | B35: MSリフォーム再販 | C35: 上馬マンション | D35: 45082 | E35: 45079 | F35: 45114 | G35: 21000000 | H35: 16000000 | I35: 0 | J35: =IF(F35="","",IFERROR(INDEX(設定!$A$8:$A$15,MATCH(F35,設定!$B$8:$B$15,1)),"対象外")) -> 11期 | K35: =IF(F35="","未売却",IF(F35<=設定!$B$3,"実績","予定")) -> 実績 | L35: =IF(F35="",0,IF(OR(設定!$B$4="全て",K35="実績"),1,0)) -> 1 | M35: =IF(OR(G35="",H35=""),"",G35-H35-I35) -> 5000000 | N35: =IF(M35="","",M35/G35) -> 0.23809524 | O35: =IF(OR(D35="",F35=""),"",F35-D35) -> 32 | P35: =IF(G35="","",IF(INT(G35/設定!$B$5)*設定!$B$5>=100000000,TEXT(INT(G35/設定!$B$5)*設定!$B$5/100000000,"0.0")&"億",TEXT(INT(G35/設定!$B$5)*設定!$B$5/10000,"#,##0")&"万")&"〜") -> 0万〜 | Q35: 66
A36: 21 | B36: OC転売 | C36: サンパルムOC転売 | D36: 44694 | E36: 45166 | F36: 45166 | G36: 39000000 | I36: 0 | J36: =IF(F36="","",IFERROR(INDEX(設定!$A$8:$A$15,MATCH(F36,設定!$B$8:$B$15,1)),"対象外")) -> 11期 | K36: =IF(F36="","未売却",IF(F36<=設定!$B$3,"実績","予定")) -> 実績 | L36: =IF(F36="",0,IF(OR(設定!$B$4="全て",K36="実績"),1,0)) -> 1 | M36: =IF(OR(G36="",H36=""),"",G36-H36-I36) | N36: =IF(M36="","",M36/G36) | O36: =IF(OR(D36="",F36=""),"",F36-D36) -> 472 | P36: =IF(G36="","",IF(INT(G36/設定!$B$5)*設定!$B$5>=100000000,TEXT(INT(G36/設定!$B$5)*設定!$B$5/100000000,"0.0")&"億",TEXT(INT(G36/設定!$B$5)*設定!$B$5/10000,"#,##0")&"万")&"〜") -> 0万〜 | Q36: 25 | R36: 仕入原価未入力→粗利対象外
A37: 37 | B37: 条件なし土地 | C37: 東山MS土地売り | D37: 44865 | E37: 45022 | F37: 45169 | G37: 400000000 | I37: 50000000 | J37: =IF(F37="","",IFERROR(INDEX(設定!$A$8:$A$15,MATCH(F37,設定!$B$8:$B$15,1)),"対象外")) -> 11期 | K37: =IF(F37="","未売却",IF(F37<=設定!$B$3,"実績","予定")) -> 実績 | L37: =IF(F37="",0,IF(OR(設定!$B$4="全て",K37="実績"),1,0)) -> 1 | M37: =IF(OR(G37="",H37=""),"",G37-H37-I37) | N37: =IF(M37="","",M37/G37) | O37: =IF(OR(D37="",F37=""),"",F37-D37) -> 304 | P37: =IF(G37="","",IF(INT(G37/設定!$B$5)*設定!$B$5>=100000000,TEXT(INT(G37/設定!$B$5)*設定!$B$5/100000000,"0.0")&"億",TEXT(INT(G37/設定!$B$5)*設定!$B$5/10000,"#,##0")&"万")&"〜") -> 4.0億〜 | Q37: 41 | R37: 仕入原価未入力→粗利対象外
A38: 27 | B38: 新築戸建 | C38: 北寺尾2丁目新築戸建Ａ | D38: 44798 | F38: 45194 | G38: 52800000 | I38: 15000000 | J38: =IF(F38="","",IFERROR(INDEX(設定!$A$8:$A$15,MATCH(F38,設定!$B$8:$B$15,1)),"対象外")) -> 11期 | K38: =IF(F38="","未売却",IF(F38<=設定!$B$3,"実績","予定")) -> 実績 | L38: =IF(F38="",0,IF(OR(設定!$B$4="全て",K38="実績"),1,0)) -> 1 | M38: =IF(OR(G38="",H38=""),"",G38-H38-I38) | N38: =IF(M38="","",M38/G38) | O38: =IF(OR(D38="",F38=""),"",F38-D38) -> 396 | P38: =IF(G38="","",IF(INT(G38/設定!$B$5)*設定!$B$5>=100000000,TEXT(INT(G38/設定!$B$5)*設定!$B$5/100000000,"0.0")&"億",TEXT(INT(G38/設定!$B$5)*設定!$B$5/10000,"#,##0")&"万")&"〜") -> 5,000万〜 | Q38: 31 | R38: 仕入原価未入力→粗利対象外
A39: 28 | B39: 新築戸建 | C39: 北寺尾2丁目新築戸建Ｂ | D39: 44798 | F39: 45194 | G39: 54800000 | I39: 15000000 | J39: =IF(F39="","",IFERROR(INDEX(設定!$A$8:$A$15,MATCH(F39,設定!$B$8:$B$15,1)),"対象外")) -> 11期 | K39: =IF(F39="","未売却",IF(F39<=設定!$B$3,"実績","予定")) -> 実績 | L39: =IF(F39="",0,IF(OR(設定!$B$4="全て",K39="実績"),1,0)) -> 1 | M39: =IF(OR(G39="",H39=""),"",G39-H39-I39) | N39: =IF(M39="","",M39/G39) | O39: =IF(OR(D39="",F39=""),"",F39-D39) -> 396 | P39: =IF(G39="","",IF(INT(G39/設定!$B$5)*設定!$B$5>=100000000,TEXT(INT(G39/設定!$B$5)*設定!$B$5/100000000,"0.0")&"億",TEXT(INT(G39/設定!$B$5)*設定!$B$5/10000,"#,##0")&"万")&"〜") -> 5,000万〜 | Q39: 32 | R39: 仕入原価未入力→粗利対象外
A40: 56 | B40: MSリフォーム再販 | C40: ｼﾘｳｽｺｰﾄ川崎南 | D40: 45015 | E40: 45219 | F40: 45260 | G40: 27650000 | H40: 28550000 | I40: 7150000 | J40: =IF(F40="","",IFERROR(INDEX(設定!$A$8:$A$15,MATCH(F40,設定!$B$8:$B$15,1)),"対象外")) -> 11期 | K40: =IF(F40="","未売却",IF(F40<=設定!$B$3,"実績","予定")) -> 実績 | L40: =IF(F40="",0,IF(OR(設定!$B$4="全て",K40="実績"),1,0)) -> 1 | M40: =IF(OR(G40="",H40=""),"",G40-H40-I40) -> -8050000 | N40: =IF(M40="","",M40/G40) -> -0.29113924 | O40: =IF(OR(D40="",F40=""),"",F40-D40) -> 245 | P40: =IF(G40="","",IF(INT(G40/設定!$B$5)*設定!$B$5>=100000000,TEXT(INT(G40/設定!$B$5)*設定!$B$5/100000000,"0.0")&"億",TEXT(INT(G40/設定!$B$5)*設定!$B$5/10000,"#,##0")&"万")&"〜") -> 0万〜 | Q40: 60 | R40: 原価が売価を上回る
A41: 82 | B41: MSリフォーム再販 | C41: ｼｬﾝﾎﾞｰﾙ互恵ビル | D41: 45194 | E41: 45234 | F41: 45270 | G41: 19500000 | H41: 15600000 | I41: 0 | J41: =IF(F41="","",IFERROR(INDEX(設定!$A$8:$A$15,MATCH(F41,設定!$B$8:$B$15,1)),"対象外")) -> 11期 | K41: =IF(F41="","未売却",IF(F41<=設定!$B$3,"実績","予定")) -> 実績 | L41: =IF(F41="",0,IF(OR(設定!$B$4="全て",K41="実績"),1,0)) -> 1 | M41: =IF(OR(G41="",H41=""),"",G41-H41-I41) -> 3900000 | N41: =IF(M41="","",M41/G41) -> 0.2 | O41: =IF(OR(D41="",F41=""),"",F41-D41) -> 76 | P41: =IF(G41="","",IF(INT(G41/設定!$B$5)*設定!$B$5>=100000000,TEXT(INT(G41/設定!$B$5)*設定!$B$5/100000000,"0.0")&"億",TEXT(INT(G41/設定!$B$5)*設定!$B$5/10000,"#,##0")&"万")&"〜") -> 0万〜 | Q41: 86
...

Sheet ①期別×種別
A1: ① 期ごとの物件種別（売却決済ベース 棟数）
A2: =" 集計対象："&設定!B4&"／基準日："&TEXT(設定!B3,"yyyy/mm/dd") -> 集計対象：全て／基準日：2026/09/29
A4: 物件種別 | B4: 10期 | C4: 11期 | D4: 12期 | E4: 13期 | F4: 14期 | G4: 15期 | H4: 合計
A5: 新築戸建 | B5: =COUNTIFS(物件データ!$B$5:$B$180,$A5,物件データ!$J$5:$J$180,B$4,物件データ!$L$5:$L$180,1) -> 17 | C5: =COUNTIFS(物件データ!$B$5:$B$180,$A5,物件データ!$J$5:$J$180,C$4,物件データ!$L$5:$L$180,1) -> 17 | D5: =COUNTIFS(物件データ!$B$5:$B$180,$A5,物件データ!$J$5:$J$180,D$4,物件データ!$L$5:$L$180,1) -> 4 | E5: =COUNTIFS(物件データ!$B$5:$B$180,$A5,物件データ!$J$5:$J$180,E$4,物件データ!$L$5:$L$180,1) -> 13 | F5: =COUNTIFS(物件データ!$B$5:$B$180,$A5,物件データ!$J$5:$J$180,F$4,物件データ!$L$5:$L$180,1) -> 7 | G5: =COUNTIFS(物件データ!$B$5:$B$180,$A5,物件データ!$J$5:$J$180,G$4,物件データ!$L$5:$L$180,1) -> 3 | H5: =SUM(B5:G5) -> 61
A6: 条件なし土地 | B6: =COUNTIFS(物件データ!$B$5:$B$180,$A6,物件データ!$J$5:$J$180,B$4,物件データ!$L$5:$L$180,1) -> 2 | C6: =COUNTIFS(物件データ!$B$5:$B$180,$A6,物件データ!$J$5:$J$180,C$4,物件データ!$L$5:$L$180,1) -> 3 | D6: =COUNTIFS(物件データ!$B$5:$B$180,$A6,物件データ!$J$5:$J$180,D$4,物件データ!$L$5:$L$180,1) -> 0 | E6: =COUNTIFS(物件データ!$B$5:$B$180,$A6,物件データ!$J$5:$J$180,E$4,物件データ!$L$5:$L$180,1) -> 4 | F6: =COUNTIFS(物件データ!$B$5:$B$180,$A6,物件データ!$J$5:$J$180,F$4,物件データ!$L$5:$L$180,1) -> 10 | G6: =COUNTIFS(物件データ!$B$5:$B$180,$A6,物件データ!$J$5:$J$180,G$4,物件データ!$L$5:$L$180,1) -> 2 | H6: =SUM(B6:G6) -> 21
A7: MSリフォーム再販 | B7: =COUNTIFS(物件データ!$B$5:$B$180,$A7,物件データ!$J$5:$J$180,B$4,物件データ!$L$5:$L$180,1) -> 5 | C7: =COUNTIFS(物件データ!$B$5:$B$180,$A7,物件データ!$J$5:$J$180,C$4,物件データ!$L$5:$L$180,1) -> 5 | D7: =COUNTIFS(物件データ!$B$5:$B$180,$A7,物件データ!$J$5:$J$180,D$4,物件データ!$L$5:$L$180,1) -> 0 | E7: =COUNTIFS(物件データ!$B$5:$B$180,$A7,物件データ!$J$5:$J$180,E$4,物件データ!$L$5:$L$180,1) -> 4 | F7: =COUNTIFS(物件データ!$B$5:$B$180,$A7,物件データ!$J$5:$J$180,F$4,物件データ!$L$5:$L$180,1) -> 5 | G7: =COUNTIFS(物件データ!$B$5:$B$180,$A7,物件データ!$J$5:$J$180,G$4,物件データ!$L$5:$L$180,1) -> 1 | H7: =SUM(B7:G7) -> 20
A8: 戸建リフォーム再販 | B8: =COUNTIFS(物件データ!$B$5:$B$180,$A8,物件データ!$J$5:$J$180,B$4,物件データ!$L$5:$L$180,1) -> 4 | C8: =COUNTIFS(物件データ!$B$5:$B$180,$A8,物件データ!$J$5:$J$180,C$4,物件データ!$L$5:$L$180,1) -> 3 | D8: =COUNTIFS(物件データ!$B$5:$B$180,$A8,物件データ!$J$5:$J$180,D$4,物件データ!$L$5:$L$180,1) -> 1 | E8: =COUNTIFS(物件データ!$B$5:$B$180,$A8,物件データ!$J$5:$J$180,E$4,物件データ!$L$5:$L$180,1) -> 3 | F8: =COUNTIFS(物件データ!$B$5:$B$180,$A8,物件データ!$J$5:$J$180,F$4,物件データ!$L$5:$L$180,1) -> 3 | G8: =COUNTIFS(物件データ!$B$5:$B$180,$A8,物件データ!$J$5:$J$180,G$4,物件データ!$L$5:$L$180,1) -> 0 | H8: =SUM(B8:G8) -> 14
A9: 条件付き土地 | B9: =COUNTIFS(物件データ!$B$5:$B$180,$A9,物件データ!$J$5:$J$180,B$4,物件データ!$L$5:$L$180,1) -> 2 | C9: =COUNTIFS(物件データ!$B$5:$B$180,$A9,物件データ!$J$5:$J$180,C$4,物件データ!$L$5:$L$180,1) -> 1 | D9: =COUNTIFS(物件データ!$B$5:$B$180,$A9,物件データ!$J$5:$J$180,D$4,物件データ!$L$5:$L$180,1) -> 0 | E9: =COUNTIFS(物件データ!$B$5:$B$180,$A9,物件データ!$J$5:$J$180,E$4,物件データ!$L$5:$L$180,1) -> 3 | F9: =COUNTIFS(物件データ!$B$5:$B$180,$A9,物件データ!$J$5:$J$180,F$4,物件データ!$L$5:$L$180,1) -> 0 | G9: =COUNTIFS(物件データ!$B$5:$B$180,$A9,物件データ!$J$5:$J$180,G$4,物件データ!$L$5:$L$180,1) -> 0 | H9: =SUM(B9:G9) -> 6
A10: 立ち退き後転売土地 | B10: =COUNTIFS(物件データ!$B$5:$B$180,$A10,物件データ!$J$5:$J$180,B$4,物件データ!$L$5:$L$180,1) -> 0 | C10: =COUNTIFS(物件データ!$B$5:$B$180,$A10,物件データ!$J$5:$J$180,C$4,物件データ!$L$5:$L$180,1) -> 0 | D10: =COUNTIFS(物件データ!$B$5:$B$180,$A10,物件データ!$J$5:$J$180,D$4,物件データ!$L$5:$L$180,1) -> 1 | E10: =COUNTIFS(物件データ!$B$5:$B$180,$A10,物件データ!$J$5:$J$180,E$4,物件データ!$L$5:$L$180,1) -> 3 | F10: =COUNTIFS(物件データ!$B$5:$B$180,$A10,物件データ!$J$5:$J$180,F$4,物件データ!$L$5:$L$180,1) -> 1 | G10: =COUNTIFS(物件データ!$B$5:$B$180,$A10,物件データ!$J$5:$J$180,G$4,物件データ!$L$5:$L$180,1) -> 0 | H10: =SUM(B10:G10) -> 5
A11: 一棟収益天端 | B11: =COUNTIFS(物件データ!$B$5:$B$180,$A11,物件データ!$J$5:$J$180,B$4,物件データ!$L$5:$L$180,1) -> 0 | C11: =COUNTIFS(物件データ!$B$5:$B$180,$A11,物件データ!$J$5:$J$180,C$4,物件データ!$L$5:$L$180,1) -> 2 | D11: =COUNTIFS(物件データ!$B$5:$B$180,$A11,物件データ!$J$5:$J$180,D$4,物件データ!$L$5:$L$180,1) -> 0 | E11: =COUNTIFS(物件データ!$B$5:$B$180,$A11,物件データ!$J$5:$J$180,E$4,物件データ!$L$5:$L$180,1) -> 1 | F11: =COUNTIFS(物件データ!$B$5:$B$180,$A11,物件データ!$J$5:$J$180,F$4,物件データ!$L$5:$L$180,1) -> 1 | G11: =COUNTIFS(物件データ!$B$5:$B$180,$A11,物件データ!$J$5:$J$180,G$4,物件データ!$L$5:$L$180,1) -> 0 | H11: =SUM(B11:G11) -> 4
A12: OC転売 | B12: =COUNTIFS(物件データ!$B$5:$B$180,$A12,物件データ!$J$5:$J$180,B$4,物件データ!$L$5:$L$180,1) -> 0 | C12: =COUNTIFS(物件データ!$B$5:$B$180,$A12,物件データ!$J$5:$J$180,C$4,物件データ!$L$5:$L$180,1) -> 1 | D12: =COUNTIFS(物件データ!$B$5:$B$180,$A12,物件データ!$J$5:$J$180,D$4,物件データ!$L$5:$L$180,1) -> 0 | E12: =COUNTIFS(物件データ!$B$5:$B$180,$A12,物件データ!$J$5:$J$180,E$4,物件データ!$L$5:$L$180,1) -> 1 | F12: =COUNTIFS(物件データ!$B$5:$B$180,$A12,物件データ!$J$5:$J$180,F$4,物件データ!$L$5:$L$180,1) -> 0 | G12: =COUNTIFS(物件データ!$B$5:$B$180,$A12,物件データ!$J$5:$J$180,G$4,物件データ!$L$5:$L$180,1) -> 0 | H12: =SUM(B12:G12) -> 2
A13: JT | B13: =COUNTIFS(物件データ!$B$5:$B$180,$A13,物件データ!$J$5:$J$180,B$4,物件データ!$L$5:$L$180,1) -> 0 | C13: =COUNTIFS(物件データ!$B$5:$B$180,$A13,物件データ!$J$5:$J$180,C$4,物件データ!$L$5:$L$180,1) -> 0 | D13: =COUNTIFS(物件データ!$B$5:$B$180,$A13,物件データ!$J$5:$J$180,D$4,物件データ!$L$5:$L$180,1) -> 0 | E13: =COUNTIFS(物件データ!$B$5:$B$180,$A13,物件データ!$J$5:$J$180,E$4,物件データ!$L$5:$L$180,1) -> 1 | F13: =COUNTIFS(物件データ!$B$5:$B$180,$A13,物件データ!$J$5:$J$180,F$4,物件データ!$L$5:$L$180,1) -> 0 | G13: =COUNTIFS(物件データ!$B$5:$B$180,$A13,物件データ!$J$5:$J$180,G$4,物件データ!$L$5:$L$180,1) -> 0 | H13: =SUM(B13:G13) -> 1
A14: たちのき後転売MS | B14: =COUNTIFS(物件データ!$B$5:$B$180,$A14,物件データ!$J$5:$J$180,B$4,物件データ!$L$5:$L$180,1) -> 0 | C14: =COUNTIFS(物件データ!$B$5:$B$180,$A14,物件データ!$J$5:$J$180,C$4,物件データ!$L$5:$L$180,1) -> 0 | D14: =COUNTIFS(物件データ!$B$5:$B$180,$A14,物件データ!$J$5:$J$180,D$4,物件データ!$L$5:$L$180,1) -> 0 | E14: =COUNTIFS(物件データ!$B$5:$B$180,$A14,物件データ!$J$5:$J$180,E$4,物件データ!$L$5:$L$180,1) -> 0 | F14: =COUNTIFS(物件データ!$B$5:$B$180,$A14,物件データ!$J$5:$J$180,F$4,物件データ!$L$5:$L$180,1) -> 1 | G14: =COUNTIFS(物件データ!$B$5:$B$180,$A14,物件データ!$J$5:$J$180,G$4,物件データ!$L$5:$L$180,1) -> 0 | H14: =SUM(B14:G14) -> 1
A15: 合計 | B15: =SUM(B5:B14) -> 30 | C15: =SUM(C5:C14) -> 32 | D15: =SUM(D5:D14) -> 6 | E15: =SUM(E5:E14) -> 33 | F15: =SUM(F5:F14) -> 28 | G15: =SUM(G5:G14) -> 6 | H15: =SUM(H5:H14) -> 135
A17: 種別構成比（棟数）
A18: 物件種別 | B18: 10期 | C18: 11期 | D18: 12期 | E18: 13期 | F18: 14期 | G18: 15期 | H18: 合計
A19: 新築戸建 | B19: =IF(B$15=0,"",B5/B$15) -> 0.56666667 | C19: =IF(C$15=0,"",C5/C$15) -> 0.53125 | D19: =IF(D$15=0,"",D5/D$15) -> 0.66666667 | E19: =IF(E$15=0,"",E5/E$15) -> 0.39393939 | F19: =IF(F$15=0,"",F5/F$15) -> 0.25 | G19: =IF(G$15=0,"",G5/G$15) -> 0.5 | H19: =IF(H$15=0,"",H5/H$15) -> 0.45185185
A20: 条件なし土地 | B20: =IF(B$15=0,"",B6/B$15) -> 0.066666667 | C20: =IF(C$15=0,"",C6/C$15) -> 0.09375 | D20: =IF(D$15=0,"",D6/D$15) -> 0 | E20: =IF(E$15=0,"",E6/E$15) -> 0.12121212 | F20: =IF(F$15=0,"",F6/F$15) -> 0.35714286 | G20: =IF(G$15=0,"",G6/G$15) -> 0.33333333 | H20: =IF(H$15=0,"",H6/H$15) -> 0.15555556
A21: MSリフォーム再販 | B21: =IF(B$15=0,"",B7/B$15) -> 0.16666667 | C21: =IF(C$15=0,"",C7/C$15) -> 0.15625 | D21: =IF(D$15=0,"",D7/D$15) -> 0 | E21: =IF(E$15=0,"",E7/E$15) -> 0.12121212 | F21: =IF(F$15=0,"",F7/F$15) -> 0.17857143 | G21: =IF(G$15=0,"",G7/G$15) -> 0.16666667 | H21: =IF(H$15=0,"",H7/H$15) -> 0.14814815
A22: 戸建リフォーム再販 | B22: =IF(B$15=0,"",B8/B$15) -> 0.13333333 | C22: =IF(C$15=0,"",C8/C$15) -> 0.09375 | D22: =IF(D$15=0,"",D8/D$15) -> 0.16666667 | E22: =IF(E$15=0,"",E8/E$15) -> 0.090909091 | F22: =IF(F$15=0,"",F8/F$15) -> 0.10714286 | G22: =IF(G$15=0,"",G8/G$15) -> 0 | H22: =IF(H$15=0,"",H8/H$15) -> 0.1037037
A23: 条件付き土地 | B23: =IF(B$15=0,"",B9/B$15) -> 0.066666667 | C23: =IF(C$15=0,"",C9/C$15) -> 0.03125 | D23: =IF(D$15=0,"",D9/D$15) -> 0 | E23: =IF(E$15=0,"",E9/E$15) -> 0.090909091 | F23: =IF(F$15=0,"",F9/F$15) -> 0 | G23: =IF(G$15=0,"",G9/G$15) -> 0 | H23: =IF(H$15=0,"",H9/H$15) -> 0.044444444
A24: 立ち退き後転売土地 | B24: =IF(B$15=0,"",B10/B$15) -> 0 | C24: =IF(C$15=0,"",C10/C$15) -> 0 | D24: =IF(D$15=0,"",D10/D$15) -> 0.16666667 | E24: =IF(E$15=0,"",E10/E$15) -> 0.090909091 | F24: =IF(F$15=0,"",F10/F$15) -> 0.035714286 | G24: =IF(G$15=0,"",G10/G$15) -> 0 | H24: =IF(H$15=0,"",H10/H$15) -> 0.037037037
A25: 一棟収益天端 | B25: =IF(B$15=0,"",B11/B$15) -> 0 | C25: =IF(C$15=0,"",C11/C$15) -> 0.0625 | D25: =IF(D$15=0,"",D11/D$15) -> 0 | E25: =IF(E$15=0,"",E11/E$15) -> 0.03030303 | F25: =IF(F$15=0,"",F11/F$15) -> 0.035714286 | G25: =IF(G$15=0,"",G11/G$15) -> 0 | H25: =IF(H$15=0,"",H11/H$15) -> 0.02962963
A26: OC転売 | B26: =IF(B$15=0,"",B12/B$15) -> 0 | C26: =IF(C$15=0,"",C12/C$15) -> 0.03125 | D26: =IF(D$15=0,"",D12/D$15) -> 0 | E26: =IF(E$15=0,"",E12/E$15) -> 0.03030303 | F26: =IF(F$15=0,"",F12/F$15) -> 0 | G26: =IF(G$15=0,"",G12/G$15) -> 0 | H26: =IF(H$15=0,"",H12/H$15) -> 0.014814815
A27: JT | B27: =IF(B$15=0,"",B13/B$15) -> 0 | C27: =IF(C$15=0,"",C13/C$15) -> 0 | D27: =IF(D$15=0,"",D13/D$15) -> 0 | E27: =IF(E$15=0,"",E13/E$15) -> 0.03030303 | F27: =IF(F$15=0,"",F13/F$15) -> 0 | G27: =IF(G$15=0,"",G13/G$15) -> 0 | H27: =IF(H$15=0,"",H13/H$15) -> 0.0074074074
A28: たちのき後転売MS | B28: =IF(B$15=0,"",B14/B$15) -> 0 | C28: =IF(C$15=0,"",C14/C$15) -> 0 | D28: =IF(D$15=0,"",D14/D$15) -> 0 | E28: =IF(E$15=0,"",E14/E$15) -> 0 | F28: =IF(F$15=0,"",F14/F$15) -> 0.035714286 | G28: =IF(G$15=0,"",G14/G$15) -> 0 | H28: =IF(H$15=0,"",H14/H$15) -> 0.0074074074

Sheet ②種別別KPI
A1: ② 種別ごと・期ごとの売上高／粗利／保有日数／棟数
A2: =" 集計対象："&設定!B4&"／粗利・粗利率は仕入原価入力済の物件のみ" -> 集計対象：全て／粗利・粗利率は仕入原価入力済の物件のみ
A4: 棟数
A5: 物件種別 | B5: 10期 | C5: 11期 | D5: 12期 | E5: 13期 | F5: 14期 | G5: 15期 | H5: 合計
A6: 新築戸建 | B6: =COUNTIFS(物件データ!$L$5:$L$180,1,物件データ!$B$5:$B$180,$A6,物件データ!$J$5:$J$180,B$5) -> 17 | C6: =COUNTIFS(物件データ!$L$5:$L$180,1,物件データ!$B$5:$B$180,$A6,物件データ!$J$5:$J$180,C$5) -> 17 | D6: =COUNTIFS(物件データ!$L$5:$L$180,1,物件データ!$B$5:$B$180,$A6,物件データ!$J$5:$J$180,D$5) -> 4 | E6: =COUNTIFS(物件データ!$L$5:$L$180,1,物件データ!$B$5:$B$180,$A6,物件データ!$J$5:$J$180,E$5) -> 13 | F6: =COUNTIFS(物件データ!$L$5:$L$180,1,物件データ!$B$5:$B$180,$A6,物件データ!$J$5:$J$180,F$5) -> 7 | G6: =COUNTIFS(物件データ!$L$5:$L$180,1,物件データ!$B$5:$B$180,$A6,物件データ!$J$5:$J$180,G$5) -> 3 | H6: =COUNTIFS(物件データ!$L$5:$L$180,1,物件データ!$B$5:$B$180,$A6,物件データ!$J$5:$J$180,"?*") -> 61
A7: 条件なし土地 | B7: =COUNTIFS(物件データ!$L$5:$L$180,1,物件データ!$B$5:$B$180,$A7,物件データ!$J$5:$J$180,B$5) -> 2 | C7: =COUNTIFS(物件データ!$L$5:$L$180,1,物件データ!$B$5:$B$180,$A7,物件データ!$J$5:$J$180,C$5) -> 3 | D7: =COUNTIFS(物件データ!$L$5:$L$180,1,物件データ!$B$5:$B$180,$A7,物件データ!$J$5:$J$180,D$5) -> 0 | E7: =COUNTIFS(物件データ!$L$5:$L$180,1,物件データ!$B$5:$B$180,$A7,物件データ!$J$5:$J$180,E$5) -> 4 | F7: =COUNTIFS(物件データ!$L$5:$L$180,1,物件データ!$B$5:$B$180,$A7,物件データ!$J$5:$J$180,F$5) -> 10 | G7: =COUNTIFS(物件データ!$L$5:$L$180,1,物件データ!$B$5:$B$180,$A7,物件データ!$J$5:$J$180,G$5) -> 2 | H7: =COUNTIFS(物件データ!$L$5:$L$180,1,物件データ!$B$5:$B$180,$A7,物件データ!$J$5:$J$180,"?*") -> 21
A8: MSリフォーム再販 | B8: =COUNTIFS(物件データ!$L$5:$L$180,1,物件データ!$B$5:$B$180,$A8,物件データ!$J$5:$J$180,B$5) -> 5 | C8: =COUNTIFS(物件データ!$L$5:$L$180,1,物件データ!$B$5:$B$180,$A8,物件データ!$J$5:$J$180,C$5) -> 5 | D8: =COUNTIFS(物件データ!$L$5:$L$180,1,物件データ!$B$5:$B$180,$A8,物件データ!$J$5:$J$180,D$5) -> 0 | E8: =COUNTIFS(物件データ!$L$5:$L$180,1,物件データ!$B$5:$B$180,$A8,物件データ!$J$5:$J$180,E$5) -> 4 | F8: =COUNTIFS(物件データ!$L$5:$L$180,1,物件データ!$B$5:$B$180,$A8,物件データ!$J$5:$J$180,F$5) -> 5 | G8: =COUNTIFS(物件データ!$L$5:$L$180,1,物件データ!$B$5:$B$180,$A8,物件データ!$J$5:$J$180,G$5) -> 1 | H8: =COUNTIFS(物件データ!$L$5:$L$180,1,物件データ!$B$5:$B$180,$A8,物件データ!$J$5:$J$180,"?*") -> 20
A9: 戸建リフォーム再販 | B9: =COUNTIFS(物件データ!$L$5:$L$180,1,物件データ!$B$5:$B$180,$A9,物件データ!$J$5:$J$180,B$5) -> 4 | C9: =COUNTIFS(物件データ!$L$5:$L$180,1,物件データ!$B$5:$B$180,$A9,物件データ!$J$5:$J$180,C$5) -> 3 | D9: =COUNTIFS(物件データ!$L$5:$L$180,1,物件データ!$B$5:$B$180,$A9,物件データ!$J$5:$J$180,D$5) -> 1 | E9: =COUNTIFS(物件データ!$L$5:$L$180,1,物件データ!$B$5:$B$180,$A9,物件データ!$J$5:$J$180,E$5) -> 3 | F9: =COUNTIFS(物件データ!$L$5:$L$180,1,物件データ!$B$5:$B$180,$A9,物件データ!$J$5:$J$180,F$5) -> 3 | G9: =COUNTIFS(物件データ!$L$5:$L$180,1,物件データ!$B$5:$B$180,$A9,物件データ!$J$5:$J$180,G$5) -> 0 | H9: =COUNTIFS(物件データ!$L$5:$L$180,1,物件データ!$B$5:$B$180,$A9,物件データ!$J$5:$J$180,"?*") -> 14
A10: 条件付き土地 | B10: =COUNTIFS(物件データ!$L$5:$L$180,1,物件データ!$B$5:$B$180,$A10,物件データ!$J$5:$J$180,B$5) -> 2 | C10: =COUNTIFS(物件データ!$L$5:$L$180,1,物件データ!$B$5:$B$180,$A10,物件データ!$J$5:$J$180,C$5) -> 1 | D10: =COUNTIFS(物件データ!$L$5:$L$180,1,物件データ!$B$5:$B$180,$A10,物件データ!$J$5:$J$180,D$5) -> 0 | E10: =COUNTIFS(物件データ!$L$5:$L$180,1,物件データ!$B$5:$B$180,$A10,物件データ!$J$5:$J$180,E$5) -> 3 | F10: =COUNTIFS(物件データ!$L$5:$L$180,1,物件データ!$B$5:$B$180,$A10,物件データ!$J$5:$J$180,F$5) -> 0 | G10: =COUNTIFS(物件データ!$L$5:$L$180,1,物件データ!$B$5:$B$180,$A10,物件データ!$J$5:$J$180,G$5) -> 0 | H10: =COUNTIFS(物件データ!$L$5:$L$180,1,物件データ!$B$5:$B$180,$A10,物件データ!$J$5:$J$180,"?*") -> 6
A11: 立ち退き後転売土地 | B11: =COUNTIFS(物件データ!$L$5:$L$180,1,物件データ!$B$5:$B$180,$A11,物件データ!$J$5:$J$180,B$5) -> 0 | C11: =COUNTIFS(物件データ!$L$5:$L$180,1,物件データ!$B$5:$B$180,$A11,物件データ!$J$5:$J$180,C$5) -> 0 | D11: =COUNTIFS(物件データ!$L$5:$L$180,1,物件データ!$B$5:$B$180,$A11,物件データ!$J$5:$J$180,D$5) -> 1 | E11: =COUNTIFS(物件データ!$L$5:$L$180,1,物件データ!$B$5:$B$180,$A11,物件データ!$J$5:$J$180,E$5) -> 3 | F11: =COUNTIFS(物件データ!$L$5:$L$180,1,物件データ!$B$5:$B$180,$A11,物件データ!$J$5:$J$180,F$5) -> 1 | G11: =COUNTIFS(物件データ!$L$5:$L$180,1,物件データ!$B$5:$B$180,$A11,物件データ!$J$5:$J$180,G$5) -> 0 | H11: =COUNTIFS(物件データ!$L$5:$L$180,1,物件データ!$B$5:$B$180,$A11,物件データ!$J$5:$J$180,"?*") -> 5
A12: 一棟収益天端 | B12: =COUNTIFS(物件データ!$L$5:$L$180,1,物件データ!$B$5:$B$180,$A12,物件データ!$J$5:$J$180,B$5) -> 0 | C12: =COUNTIFS(物件データ!$L$5:$L$180,1,物件データ!$B$5:$B$180,$A12,物件データ!$J$5:$J$180,C$5) -> 2 | D12: =COUNTIFS(物件データ!$L$5:$L$180,1,物件データ!$B$5:$B$180,$A12,物件データ!$J$5:$J$180,D$5) -> 0 | E12: =COUNTIFS(物件データ!$L$5:$L$180,1,物件データ!$B$5:$B$180,$A12,物件データ!$J$5:$J$180,E$5) -> 1 | F12: =COUNTIFS(物件データ!$L$5:$L$180,1,物件データ!$B$5:$B$180,$A12,物件データ!$J$5:$J$180,F$5) -> 1 | G12: =COUNTIFS(物件データ!$L$5:$L$180,1,物件データ!$B$5:$B$180,$A12,物件データ!$J$5:$J$180,G$5) -> 0 | H12: =COUNTIFS(物件データ!$L$5:$L$180,1,物件データ!$B$5:$B$180,$A12,物件データ!$J$5:$J$180,"?*") -> 4
A13: OC転売 | B13: =COUNTIFS(物件データ!$L$5:$L$180,1,物件データ!$B$5:$B$180,$A13,物件データ!$J$5:$J$180,B$5) -> 0 | C13: =COUNTIFS(物件データ!$L$5:$L$180,1,物件データ!$B$5:$B$180,$A13,物件データ!$J$5:$J$180,C$5) -> 1 | D13: =COUNTIFS(物件データ!$L$5:$L$180,1,物件データ!$B$5:$B$180,$A13,物件データ!$J$5:$J$180,D$5) -> 0 | E13: =COUNTIFS(物件データ!$L$5:$L$180,1,物件データ!$B$5:$B$180,$A13,物件データ!$J$5:$J$180,E$5) -> 1 | F13: =COUNTIFS(物件データ!$L$5:$L$180,1,物件データ!$B$5:$B$180,$A13,物件データ!$J$5:$J$180,F$5) -> 0 | G13: =COUNTIFS(物件データ!$L$5:$L$180,1,物件データ!$B$5:$B$180,$A13,物件データ!$J$5:$J$180,G$5) -> 0 | H13: =COUNTIFS(物件データ!$L$5:$L$180,1,物件データ!$B$5:$B$180,$A13,物件データ!$J$5:$J$180,"?*") -> 2
A14: JT | B14: =COUNTIFS(物件データ!$L$5:$L$180,1,物件データ!$B$5:$B$180,$A14,物件データ!$J$5:$J$180,B$5) -> 0 | C14: =COUNTIFS(物件データ!$L$5:$L$180,1,物件データ!$B$5:$B$180,$A14,物件データ!$J$5:$J$180,C$5) -> 0 | D14: =COUNTIFS(物件データ!$L$5:$L$180,1,物件データ!$B$5:$B$180,$A14,物件データ!$J$5:$J$180,D$5) -> 0 | E14: =COUNTIFS(物件データ!$L$5:$L$180,1,物件データ!$B$5:$B$180,$A14,物件データ!$J$5:$J$180,E$5) -> 1 | F14: =COUNTIFS(物件データ!$L$5:$L$180,1,物件データ!$B$5:$B$180,$A14,物件データ!$J$5:$J$180,F$5) -> 0 | G14: =COUNTIFS(物件データ!$L$5:$L$180,1,物件データ!$B$5:$B$180,$A14,物件データ!$J$5:$J$180,G$5) -> 0 | H14: =COUNTIFS(物件データ!$L$5:$L$180,1,物件データ!$B$5:$B$180,$A14,物件データ!$J$5:$J$180,"?*") -> 1
A15: たちのき後転売MS | B15: =COUNTIFS(物件データ!$L$5:$L$180,1,物件データ!$B$5:$B$180,$A15,物件データ!$J$5:$J$180,B$5) -> 0 | C15: =COUNTIFS(物件データ!$L$5:$L$180,1,物件データ!$B$5:$B$180,$A15,物件データ!$J$5:$J$180,C$5) -> 0 | D15: =COUNTIFS(物件データ!$L$5:$L$180,1,物件データ!$B$5:$B$180,$A15,物件データ!$J$5:$J$180,D$5) -> 0 | E15: =COUNTIFS(物件データ!$L$5:$L$180,1,物件データ!$B$5:$B$180,$A15,物件データ!$J$5:$J$180,E$5) -> 0 | F15: =COUNTIFS(物件データ!$L$5:$L$180,1,物件データ!$B$5:$B$180,$A15,物件データ!$J$5:$J$180,F$5) -> 1 | G15: =COUNTIFS(物件データ!$L$5:$L$180,1,物件データ!$B$5:$B$180,$A15,物件データ!$J$5:$J$180,G$5) -> 0 | H15: =COUNTIFS(物件データ!$L$5:$L$180,1,物件データ!$B$5:$B$180,$A15,物件データ!$J$5:$J$180,"?*") -> 1
A16: 合計 | B16: =SUM(B6:B15) -> 30 | C16: =SUM(C6:C15) -> 32 | D16: =SUM(D6:D15) -> 6 | E16: =SUM(E6:E15) -> 33 | F16: =SUM(F6:F15) -> 28 | G16: =SUM(G6:G15) -> 6 | H16: =SUM(H6:H15) -> 135
A18: 売上高（円）
A19: 物件種別 | B19: 10期 | C19: 11期 | D19: 12期 | E19: 13期 | F19: 14期 | G19: 15期 | H19: 合計
A20: 新築戸建 | B20: =SUMIFS(物件データ!$G$5:$G$180,物件データ!$L$5:$L$180,1,物件データ!$B$5:$B$180,$A20,物件データ!$J$5:$J$180,B$19) -> 958000000 | C20: =SUMIFS(物件データ!$G$5:$G$180,物件データ!$L$5:$L$180,1,物件データ!$B$5:$B$180,$A20,物件データ!$J$5:$J$180,C$19) -> 1268600000 | D20: =SUMIFS(物件データ!$G$5:$G$180,物件データ!$L$5:$L$180,1,物件データ!$B$5:$B$180,$A20,物件データ!$J$5:$J$180,D$19) -> 248500000 | E20: =SUMIFS(物件データ!$G$5:$G$180,物件データ!$L$5:$L$180,1,物件データ!$B$5:$B$180,$A20,物件データ!$J$5:$J$180,E$19) -> 714500000 | F20: =SUMIFS(物件データ!$G$5:$G$180,物件データ!$L$5:$L$180,1,物件データ!$B$5:$B$180,$A20,物件データ!$J$5:$J$180,F$19) -> 793500000 | G20: =SUMIFS(物件データ!$G$5:$G$180,物件データ!$L$5:$L$180,1,物件データ!$B$5:$B$180,$A20,物件データ!$J$5:$J$180,G$19) -> 150300000 | H20: =SUMIFS(物件データ!$G$5:$G$180,物件データ!$L$5:$L$180,1,物件データ!$B$5:$B$180,$A20,物件データ!$J$5:$J$180,"?*") -> 4133400000
A21: 条件なし土地 | B21: =SUMIFS(物件データ!$G$5:$G$180,物件データ!$L$5:$L$180,1,物件データ!$B$5:$B$180,$A21,物件データ!$J$5:$J$180,B$19) -> 219000000 | C21: =SUMIFS(物件データ!$G$5:$G$180,物件データ!$L$5:$L$180,1,物件データ!$B$5:$B$180,$A21,物件データ!$J$5:$J$180,C$19) -> 529400000 | D21: =SUMIFS(物件データ!$G$5:$G$180,物件データ!$L$5:$L$180,1,物件データ!$B$5:$B$180,$A21,物件データ!$J$5:$J$180,D$19) -> 0 | E21: =SUMIFS(物件データ!$G$5:$G$180,物件データ!$L$5:$L$180,1,物件データ!$B$5:$B$180,$A21,物件データ!$J$5:$J$180,E$19) -> 260800000 | F21: =SUMIFS(物件データ!$G$5:$G$180,物件データ!$L$5:$L$180,1,物件データ!$B$5:$B$180,$A21,物件データ!$J$5:$J$180,F$19) -> 1212000000 | G21: =SUMIFS(物件データ!$G$5:$G$180,物件データ!$L$5:$L$180,1,物件データ!$B$5:$B$180,$A21,物件データ!$J$5:$J$180,G$19) -> 249800000 | H21: =SUMIFS(物件データ!$G$5:$G$180,物件データ!$L$5:$L$180,1,物件データ!$B$5:$B$180,$A21,物件データ!$J$5:$J$180,"?*") -> 2471000000
A22: MSリフォーム再販 | B22: =SUMIFS(物件データ!$G$5:$G$180,物件データ!$L$5:$L$180,1,物件データ!$B$5:$B$180,$A22,物件データ!$J$5:$J$180,B$19) -> 281600000 | C22: =SUMIFS(物件データ!$G$5:$G$180,物件データ!$L$5:$L$180,1,物件データ!$B$5:$B$180,$A22,物件データ!$J$5:$J$180,C$19) -> 196850000 | D22: =SUMIFS(物件データ!$G$5:$G$180,物件データ!$L$5:$L$180,1,物件データ!$B$5:$B$180,$A22,物件データ!$J$5:$J$180,D$19) -> 0 | E22: =SUMIFS(物件データ!$G$5:$G$180,物件データ!$L$5:$L$180,1,物件データ!$B$5:$B$180,$A22,物件データ!$J$5:$J$180,E$19) -> 142800000 | F22: =SUMIFS(物件データ!$G$5:$G$180,物件データ!$L$5:$L$180,1,物件データ!$B$5:$B$180,$A22,物件データ!$J$5:$J$180,F$19) -> 164000000 | G22: =SUMIFS(物件データ!$G$5:$G$180,物件データ!$L$5:$L$180,1,物件データ!$B$5:$B$180,$A22,物件データ!$J$5:$J$180,G$19) -> 29800000 | H22: =SUMIFS(物件データ!$G$5:$G$180,物件データ!$L$5:$L$180,1,物件データ!$B$5:$B$180,$A22,物件データ!$J$5:$J$180,"?*") -> 815050000
A23: 戸建リフォーム再販 | B23: =SUMIFS(物件データ!$G$5:$G$180,物件データ!$L$5:$L$180,1,物件データ!$B$5:$B$180,$A23,物件データ!$J$5:$J$180,B$19) -> 303200000 | C23: =SUMIFS(物件データ!$G$5:$G$180,物件データ!$L$5:$L$180,1,物件データ!$B$5:$B$180,$A23,物件データ!$J$5:$J$180,C$19) -> 162800000 | D23: =SUMIFS(物件データ!$G$5:$G$180,物件データ!$L$5:$L$180,1,物件データ!$B$5:$B$180,$A23,物件データ!$J$5:$J$180,D$19) -> 74800000 | E23: =SUMIFS(物件データ!$G$5:$G$180,物件データ!$L$5:$L$180,1,物件データ!$B$5:$B$180,$A23,物件データ!$J$5:$J$180,E$19) -> 139400000 | F23: =SUMIFS(物件データ!$G$5:$G$180,物件データ!$L$5:$L$180,1,物件データ!$B$5:$B$180,$A23,物件データ!$J$5:$J$180,F$19) -> 310700000 | G23: =SUMIFS(物件データ!$G$5:$G$180,物件データ!$L$5:$L$180,1,物件データ!$B$5:$B$180,$A23,物件データ!$J$5:$J$180,G$19) -> 0 | H23: =SUMIFS(物件データ!$G$5:$G$180,物件データ!$L$5:$L$180,1,物件データ!$B$5:$B$180,$A23,物件データ!$J$5:$J$180,"?*") -> 990900000
A24: 条件付き土地 | B24: =SUMIFS(物件データ!$G$5:$G$180,物件データ!$L$5:$L$180,1,物件データ!$B$5:$B$180,$A24,物件データ!$J$5:$J$180,B$19) -> 107700000 | C24: =SUMIFS(物件データ!$G$5:$G$180,物件データ!$L$5:$L$180,1,物件データ!$B$5:$B$180,$A24,物件データ!$J$5:$J$180,C$19) -> 41500000 | D24: =SUMIFS(物件データ!$G$5:$G$180,物件データ!$L$5:$L$180,1,物件データ!$B$5:$B$180,$A24,物件データ!$J$5:$J$180,D$19) -> 0 | E24: =SUMIFS(物件データ!$G$5:$G$180,物件データ!$L$5:$L$180,1,物件データ!$B$5:$B$180,$A24,物件データ!$J$5:$J$180,E$19) -> 188400000 | F24: =SUMIFS(物件データ!$G$5:$G$180,物件データ!$L$5:$L$180,1,物件データ!$B$5:$B$180,$A24,物件データ!$J$5:$J$180,F$19) -> 0 | G24: =SUMIFS(物件データ!$G$5:$G$180,物件データ!$L$5:$L$180,1,物件データ!$B$5:$B$180,$A24,物件データ!$J$5:$J$180,G$19) -> 0 | H24: =SUMIFS(物件データ!$G$5:$G$180,物件データ!$L$5:$L$180,1,物件データ!$B$5:$B$180,$A24,物件データ!$J$5:$J$180,"?*") -> 337600000
A25: 立ち退き後転売土地 | B25: =SUMIFS(物件データ!$G$5:$G$180,物件データ!$L$5:$L$180,1,物件データ!$B$5:$B$180,$A25,物件データ!$J$5:$J$180,B$19) -> 0 | C25: =SUMIFS(物件データ!$G$5:$G$180,物件データ!$L$5:$L$180,1,物件データ!$B$5:$B$180,$A25,物件データ!$J$5:$J$180,C$19) -> 0 | D25: =SUMIFS(物件データ!$G$5:$G$180,物件データ!$L$5:$L$180,1,物件データ!$B$5:$B$180,$A25,物件データ!$J$5:$J$180,D$19) -> 99800000 | E25: =SUMIFS(物件データ!$G$5:$G$180,物件データ!$L$5:$L$180,1,物件データ!$B$5:$B$180,$A25,物件データ!$J$5:$J$180,E$19) -> 127700000 | F25: =SUMIFS(物件データ!$G$5:$G$180,物件データ!$L$5:$L$180,1,物件データ!$B$5:$B$180,$A25,物件データ!$J$5:$J$180,F$19) -> 128000000 | G25: =SUMIFS(物件データ!$G$5:$G$180,物件データ!$L$5:$L$180,1,物件データ!$B$5:$B$180,$A25,物件データ!$J$5:$J$180,G$19) -> 0 | H25: =SUMIFS(物件データ!$G$5:$G$180,物件データ!$L$5:$L$180,1,物件データ!$B$5:$B$180,$A25,物件データ!$J$5:$J$180,"?*") -> 355500000
A26: 一棟収益天端 | B26: =SUMIFS(物件データ!$G$5:$G$180,物件データ!$L$5:$L$180,1,物件データ!$B$5:$B$180,$A26,物件データ!$J$5:$J$180,B$19) -> 0 | C26: =SUMIFS(物件データ!$G$5:$G$180,物件データ!$L$5:$L$180,1,物件データ!$B$5:$B$180,$A26,物件データ!$J$5:$J$180,C$19) -> 173500000 | D26: =SUMIFS(物件データ!$G$5:$G$180,物件データ!$L$5:$L$180,1,物件データ!$B$5:$B$180,$A26,物件データ!$J$5:$J$180,D$19) -> 0 | E26: =SUMIFS(物件データ!$G$5:$G$180,物件データ!$L$5:$L$180,1,物件データ!$B$5:$B$180,$A26,物件データ!$J$5:$J$180,E$19) -> 110000000 | F26: =SUMIFS(物件データ!$G$5:$G$180,物件データ!$L$5:$L$180,1,物件データ!$B$5:$B$180,$A26,物件データ!$J$5:$J$180,F$19) -> 230000000 | G26: =SUMIFS(物件データ!$G$5:$G$180,物件データ!$L$5:$L$180,1,物件データ!$B$5:$B$180,$A26,物件データ!$J$5:$J$180,G$19) -> 0 | H26: =SUMIFS(物件データ!$G$5:$G$180,物件データ!$L$5:$L$180,1,物件データ!$B$5:$B$180,$A26,物件データ!$J$5:$J$180,"?*") -> 513500000
A27: OC転売 | B27: =SUMIFS(物件データ!$G$5:$G$180,物件データ!$L$5:$L$180,1,物件データ!$B$5:$B$180,$A27,物件データ!$J$5:$J$180,B$19) -> 0 | C27: =SUMIFS(物件データ!$G$5:$G$180,物件データ!$L$5:$L$180,1,物件データ!$B$5:$B$180,$A27,物件データ!$J$5:$J$180,C$19) -> 39000000 | D27: =SUMIFS(物件データ!$G$5:$G$180,物件データ!$L$5:$L$180,1,物件データ!$B$5:$B$180,$A27,物件データ!$J$5:$J$180,D$19) -> 0 | E27: =SUMIFS(物件データ!$G$5:$G$180,物件データ!$L$5:$L$180,1,物件データ!$B$5:$B$180,$A27,物件データ!$J$5:$J$180,E$19) -> 102000000 | F27: =SUMIFS(物件データ!$G$5:$G$180,物件データ!$L$5:$L$180,1,物件データ!$B$5:$B$180,$A27,物件データ!$J$5:$J$180,F$19) -> 0 | G27: =SUMIFS(物件データ!$G$5:$G$180,物件データ!$L$5:$L$180,1,物件データ!$B$5:$B$180,$A27,物件データ!$J$5:$J$180,G$19) -> 0 | H27: =SUMIFS(物件データ!$G$5:$G$180,物件データ!$L$5:$L$180,1,物件データ!$B$5:$B$180,$A27,物件データ!$J$5:$J$180,"?*") -> 141000000
A28: JT | B28: =SUMIFS(物件データ!$G$5:$G$180,物件データ!$L$5:$L$180,1,物件データ!$B$5:$B$180,$A28,物件データ!$J$5:$J$180,B$19) -> 0 | C28: =SUMIFS(物件データ!$G$5:$G$180,物件データ!$L$5:$L$180,1,物件データ!$B$5:$B$180,$A28,物件データ!$J$5:$J$180,C$19) -> 0 | D28: =SUMIFS(物件データ!$G$5:$G$180,物件データ!$L$5:$L$180,1,物件データ!$B$5:$B$180,$A28,物件データ!$J$5:$J$180,D$19) -> 0 | E28: =SUMIFS(物件データ!$G$5:$G$180,物件データ!$L$5:$L$180,1,物件データ!$B$5:$B$180,$A28,物件データ!$J$5:$J$180,E$19) -> 320000000 | F28: =SUMIFS(物件データ!$G$5:$G$180,物件データ!$L$5:$L$180,1,物件データ!$B$5:$B$180,$A28,物件データ!$J$5:$J$180,F$19) -> 0 | G28: =SUMIFS(物件データ!$G$5:$G$180,物件データ!$L$5:$L$180,1,物件データ!$B$5:$B$180,$A28,物件データ!$J$5:$J$180,G$19) -> 0 | H28: =SUMIFS(物件データ!$G$5:$G$180,物件データ!$L$5:$L$180,1,物件データ!$B$5:$B$180,$A28,物件データ!$J$5:$J$180,"?*") -> 320000000
A29: たちのき後転売MS | B29: =SUMIFS(物件データ!$G$5:$G$180,物件データ!$L$5:$L$180,1,物件データ!$B$5:$B$180,$A29,物件データ!$J$5:$J$180,B$19) -> 0 | C29: =SUMIFS(物件データ!$G$5:$G$180,物件データ!$L$5:$L$180,1,物件データ!$B$5:$B$180,$A29,物件データ!$J$5:$J$180,C$19) -> 0 | D29: =SUMIFS(物件データ!$G$5:$G$180,物件データ!$L$5:$L$180,1,物件データ!$B$5:$B$180,$A29,物件データ!$J$5:$J$180,D$19) -> 0 | E29: =SUMIFS(物件データ!$G$5:$G$180,物件データ!$L$5:$L$180,1,物件データ!$B$5:$B$180,$A29,物件データ!$J$5:$J$180,E$19) -> 0 | F29: =SUMIFS(物件データ!$G$5:$G$180,物件データ!$L$5:$L$180,1,物件データ!$B$5:$B$180,$A29,物件データ!$J$5:$J$180,F$19) -> 37000000 | G29: =SUMIFS(物件データ!$G$5:$G$180,物件データ!$L$5:$L$180,1,物件データ!$B$5:$B$180,$A29,物件データ!$J$5:$J$180,G$19) -> 0 | H29: =SUMIFS(物件データ!$G$5:$G$180,物件データ!$L$5:$L$180,1,物件データ!$B$5:$B$180,$A29,物件データ!$J$5:$J$180,"?*") -> 37000000
A30: 合計 | B30: =SUM(B20:B29) -> 1869500000 | C30: =SUM(C20:C29) -> 2411650000 | D30: =SUM(D20:D29) -> 423100000 | E30: =SUM(E20:E29) -> 2105600000 | F30: =SUM(F20:F29) -> 2875200000 | G30: =SUM(G20:G29) -> 429900000 | H30: =SUM(H20:H29) -> 10114950000
A32: 粗利（円）※原価入力済のみ
A33: 物件種別 | B33: 10期 | C33: 11期 | D33: 12期 | E33: 13期 | F33: 14期 | G33: 15期 | H33: 合計
A34: 新築戸建 | B34: =SUMIFS(物件データ!$M$5:$M$180,物件データ!$L$5:$L$180,1,物件データ!$B$5:$B$180,$A34,物件データ!$J$5:$J$180,B$33) -> 0 | C34: =SUMIFS(物件データ!$M$5:$M$180,物件データ!$L$5:$L$180,1,物件データ!$B$5:$B$180,$A34,物件データ!$J$5:$J$180,C$33) -> 183010000 | D34: =SUMIFS(物件データ!$M$5:$M$180,物件データ!$L$5:$L$180,1,物件データ!$B$5:$B$180,$A34,物件データ!$J$5:$J$180,D$33) -> 33670000 | E34: =SUMIFS(物件データ!$M$5:$M$180,物件データ!$L$5:$L$180,1,物件データ!$B$5:$B$180,$A34,物件データ!$J$5:$J$180,E$33) -> 75200000 | F34: =SUMIFS(物件データ!$M$5:$M$180,物件データ!$L$5:$L$180,1,物件データ!$B$5:$B$180,$A34,物件データ!$J$5:$J$180,F$33) -> 158785000 | G34: =SUMIFS(物件データ!$M$5:$M$180,物件データ!$L$5:$L$180,1,物件データ!$B$5:$B$180,$A34,物件データ!$J$5:$J$180,G$33) -> 25000000 | H34: =SUMIFS(物件データ!$M$5:$M$180,物件データ!$L$5:$L$180,1,物件データ!$B$5:$B$180,$A34,物件データ!$J$5:$J$180,"?*") -> 475665000
A35: 条件なし土地 | B35: =SUMIFS(物件データ!$M$5:$M$180,物件データ!$L$5:$L$180,1,物件データ!$B$5:$B$180,$A35,物件データ!$J$5:$J$180,B$33) -> 28786000 | C35: =SUMIFS(物件データ!$M$5:$M$180,物件データ!$L$5:$L$180,1,物件データ!$B$5:$B$180,$A35,物件データ!$J$5:$J$180,C$33) -> 17200000 | D35: =SUMIFS(物件データ!$M$5:$M$180,物件データ!$L$5:$L$180,1,物件データ!$B$5:$B$180,$A35,物件データ!$J$5:$J$180,D$33) -> 0 | E35: =SUMIFS(物件データ!$M$5:$M$180,物件データ!$L$5:$L$180,1,物件データ!$B$5:$B$180,$A35,物件データ!$J$5:$J$180,E$33) -> 52461000 | F35: =SUMIFS(物件データ!$M$5:$M$180,物件データ!$L$5:$L$180,1,物件データ!$B$5:$B$180,$A35,物件データ!$J$5:$J$180,F$33) -> 251950000 | G35: =SUMIFS(物件データ!$M$5:$M$180,物件データ!$L$5:$L$180,1,物件データ!$B$5:$B$180,$A35,物件データ!$J$5:$J$180,G$33) -> -10216000 | H35: =SUMIFS(物件データ!$M$5:$M$180,物件データ!$L$5:$L$180,1,物件データ!$B$5:$B$180,$A35,物件データ!$J$5:$J$180,"?*") -> 340181000
A36: MSリフォーム再販 | B36: =SUMIFS(物件データ!$M$5:$M$180,物件データ!$L$5:$L$180,1,物件データ!$B$5:$B$180,$A36,物件データ!$J$5:$J$180,B$33) -> 0 | C36: =SUMIFS(物件データ!$M$5:$M$180,物件データ!$L$5:$L$180,1,物件データ!$B$5:$B$180,$A36,物件データ!$J$5:$J$180,C$33) -> 12260000 | D36: =SUMIFS(物件データ!$M$5:$M$180,物件データ!$L$5:$L$180,1,物件データ!$B$5:$B$180,$A36,物件データ!$J$5:$J$180,D$33) -> 0 | E36: =SUMIFS(物件データ!$M$5:$M$180,物件データ!$L$5:$L$180,1,物件データ!$B$5:$B$180,$A36,物件データ!$J$5:$J$180,E$33) -> -8750000 | F36: =SUMIFS(物件データ!$M$5:$M$180,物件データ!$L$5:$L$180,1,物件データ!$B$5:$B$180,$A36,物件データ!$J$5:$J$180,F$33) -> 24000000 | G36: =SUMIFS(物件データ!$M$5:$M$180,物件データ!$L$5:$L$180,1,物件データ!$B$5:$B$180,$A36,物件データ!$J$5:$J$180,G$33) -> 8690000 | H36: =SUMIFS(物件データ!$M$5:$M$180,物件データ!$L$5:$L$180,1,物件データ!$B$5:$B$180,$A36,物件データ!$J$5:$J$180,"?*") -> 36200000
A37: 戸建リフォーム再販 | B37: =SUMIFS(物件データ!$M$5:$M$180,物件データ!$L$5:$L$180,1,物件データ!$B$5:$B$180,$A37,物件データ!$J$5:$J$180,B$33) -> 10342000 | C37: =SUMIFS(物件データ!$M$5:$M$180,物件データ!$L$5:$L$180,1,物件データ!$B$5:$B$180,$A37,物件データ!$J$5:$J$180,C$33) -> 23500000 | D37: =SUMIFS(物件データ!$M$5:$M$180,物件データ!$L$5:$L$180,1,物件データ!$B$5:$B$180,$A37,物件データ!$J$5:$J$180,D$33) -> 13000000 | E37: =SUMIFS(物件データ!$M$5:$M$180,物件データ!$L$5:$L$180,1,物件データ!$B$5:$B$180,$A37,物件データ!$J$5:$J$180,E$33) -> 18600000 | F37: =SUMIFS(物件データ!$M$5:$M$180,物件データ!$L$5:$L$180,1,物件データ!$B$5:$B$180,$A37,物件データ!$J$5:$J$180,F$33) -> 36400000 | G37: =SUMIFS(物件データ!$M$5:$M$180,物件データ!$L$5:$L$180,1,物件データ!$B$5:$B$180,$A37,物件データ!$J$5:$J$180,G$33) -> 0 | H37: =SUMIFS(物件データ!$M$5:$M$180,物件データ!$L$5:$L$180,1,物件データ!$B$5:$B$180,$A37,物件データ!$J$5:$J$180,"?*") -> 101842000
A38: 条件付き土地 | B38: =SUMIFS(物件データ!$M$5:$M$180,物件データ!$L$5:$L$180,1,物件データ!$B$5:$B$180,$A38,物件データ!$J$5:$J$180,B$33) -> 9033600 | C38: =SUMIFS(物件データ!$M$5:$M$180,物件データ!$L$5:$L$180,1,物件データ!$B$5:$B$180,$A38,物件データ!$J$5:$J$180,C$33) -> 10950000 | D38: =SUMIFS(物件データ!$M$5:$M$180,物件データ!$L$5:$L$180,1,物件データ!$B$5:$B$180,$A38,物件データ!$J$5:$J$180,D$33) -> 0 | E38: =SUMIFS(物件データ!$M$5:$M$180,物件データ!$L$5:$L$180,1,物件データ!$B$5:$B$180,$A38,物件データ!$J$5:$J$180,E$33) -> 41850000 | F38: =SUMIFS(物件データ!$M$5:$M$180,物件データ!$L$5:$L$180,1,物件データ!$B$5:$B$180,$A38,物件データ!$J$5:$J$180,F$33) -> 0 | G38: =SUMIFS(物件データ!$M$5:$M$180,物件データ!$L$5:$L$180,1,物件データ!$B$5:$B$180,$A38,物件データ!$J$5:$J$180,G$33) -> 0 | H38: =SUMIFS(物件データ!$M$5:$M$180,物件データ!$L$5:$L$180,1,物件データ!$B$5:$B$180,$A38,物件データ!$J$5:$J$180,"?*") -> 61833600
A39: 立ち退き後転売土地 | B39: =SUMIFS(物件データ!$M$5:$M$180,物件データ!$L$5:$L$180,1,物件データ!$B$5:$B$180,$A39,物件データ!$J$5:$J$180,B$33) -> 0 | C39: =SUMIFS(物件データ!$M$5:$M$180,物件データ!$L$5:$L$180,1,物件データ!$B$5:$B$180,$A39,物件データ!$J$5:$J$180,C$33) -> 0 | D39: =SUMIFS(物件データ!$M$5:$M$180,物件データ!$L$5:$L$180,1,物件データ!$B$5:$B$180,$A39,物件データ!$J$5:$J$180,D$33) -> 25200000 | E39: =SUMIFS(物件データ!$M$5:$M$180,物件データ!$L$5:$L$180,1,物件データ!$B$5:$B$180,$A39,物件データ!$J$5:$J$180,E$33) -> 19230000 | F39: =SUMIFS(物件データ!$M$5:$M$180,物件データ!$L$5:$L$180,1,物件データ!$B$5:$B$180,$A39,物件データ!$J$5:$J$180,F$33) -> 13606090 | G39: =SUMIFS(物件データ!$M$5:$M$180,物件データ!$L$5:$L$180,1,物件データ!$B$5:$B$180,$A39,物件データ!$J$5:$J$180,G$33) -> 0 | H39: =SUMIFS(物件データ!$M$5:$M$180,物件データ!$L$5:$L$180,1,物件データ!$B$5:$B$180,$A39,物件データ!$J$5:$J$180,"?*") -> 58036090
A40: 一棟収益天端 | B40: =SUMIFS(物件データ!$M$5:$M$180,物件データ!$L$5:$L$180,1,物件データ!$B$5:$B$180,$A40,物件データ!$J$5:$J$180,B$33) -> 0 | C40: =SUMIFS(物件データ!$M$5:$M$180,物件データ!$L$5:$L$180,1,物件データ!$B$5:$B$180,$A40,物件データ!$J$5:$J$180,C$33) -> 33500000 | D40: =SUMIFS(物件データ!$M$5:$M$180,物件データ!$L$5:$L$180,1,物件データ!$B$5:$B$180,$A40,物件データ!$J$5:$J$180,D$33) -> 0 | E40: =SUMIFS(物件データ!$M$5:$M$180,物件データ!$L$5:$L$180,1,物件データ!$B$5:$B$180,$A40,物件データ!$J$5:$J$180,E$33) -> 9800000 | F40: =SUMIFS(物件データ!$M$5:$M$180,物件データ!$L$5:$L$180,1,物件データ!$B$5:$B$180,$A40,物件データ!$J$5:$J$180,F$33) -> 17000000 | G40: =SUMIFS(物件データ!$M$5:$M$180,物件データ!$L$5:$L$180,1,物件データ!$B$5:$B$180,$A40,物件データ!$J$5:$J$180,G$33) -> 0 | H40: =SUMIFS(物件データ!$M$5:$M$180,物件データ!$L$5:$L$180,1,物件データ!$B$5:$B$180,$A40,物件データ!$J$5:$J$180,"?*") -> 60300000
A41: OC転売 | B41: =SUMIFS(物件データ!$M$5:$M$180,物件データ!$L$5:$L$180,1,物件データ!$B$5:$B$180,$A41,物件データ!$J$5:$J$180,B$33) -> 0 | C41: =SUMIFS(物件データ!$M$5:$M$180,物件データ!$L$5:$L$180,1,物件データ!$B$5:$B$180,$A41,物件データ!$J$5:$J$180,C$33) -> 0 | D41: =SUMIFS(物件データ!$M$5:$M$180,物件データ!$L$5:$L$180,1,物件データ!$B$5:$B$180,$A41,物件データ!$J$5:$J$180,D$33) -> 0 | E41: =SUMIFS(物件データ!$M$5:$M$180,物件データ!$L$5:$L$180,1,物件データ!$B$5:$B$180,$A41,物件データ!$J$5:$J$180,E$33) -> 13300000 | F41: =SUMIFS(物件データ!$M$5:$M$180,物件データ!$L$5:$L$180,1,物件データ!$B$5:$B$180,$A41,物件データ!$J$5:$J$180,F$33) -> 0 | G41: =SUMIFS(物件データ!$M$5:$M$180,物件データ!$L$5:$L$180,1,物件データ!$B$5:$B$180,$A41,物件データ!$J$5:$J$180,G$33) -> 0 | H41: =SUMIFS(物件データ!$M$5:$M$180,物件データ!$L$5:$L$180,1,物件データ!$B$5:$B$180,$A41,物件データ!$J$5:$J$180,"?*") -> 13300000
A42: JT | B42: =SUMIFS(物件データ!$M$5:$M$180,物件データ!$L$5:$L$180,1,物件データ!$B$5:$B$180,$A42,物件データ!$J$5:$J$180,B$33) -> 0 | C42: =SUMIFS(物件データ!$M$5:$M$180,物件データ!$L$5:$L$180,1,物件データ!$B$5:$B$180,$A42,物件データ!$J$5:$J$180,C$33) -> 0 | D42: =SUMIFS(物件データ!$M$5:$M$180,物件データ!$L$5:$L$180,1,物件データ!$B$5:$B$180,$A42,物件データ!$J$5:$J$180,D$33) -> 0 | E42: =SUMIFS(物件データ!$M$5:$M$180,物件データ!$L$5:$L$180,1,物件データ!$B$5:$B$180,$A42,物件データ!$J$5:$J$180,E$33) -> 77750000 | F42: =SUMIFS(物件データ!$M$5:$M$180,物件データ!$L$5:$L$180,1,物件データ!$B$5:$B$180,$A42,物件データ!$J$5:$J$180,F$33) -> 0 | G42: =SUMIFS(物件データ!$M$5:$M$180,物件データ!$L$5:$L$180,1,物件データ!$B$5:$B$180,$A42,物件データ!$J$5:$J$180,G$33) -> 0 | H42: =SUMIFS(物件データ!$M$5:$M$180,物件データ!$L$5:$L$180,1,物件データ!$B$5:$B$180,$A42,物件データ!$J$5:$J$180,"?*") -> 77750000
A43: たちのき後転売MS | B43: =SUMIFS(物件データ!$M$5:$M$180,物件データ!$L$5:$L$180,1,物件データ!$B$5:$B$180,$A43,物件データ!$J$5:$J$180,B$33) -> 0 | C43: =SUMIFS(物件データ!$M$5:$M$180,物件データ!$L$5:$L$180,1,物件データ!$B$5:$B$180,$A43,物件データ!$J$5:$J$180,C$33) -> 0 | D43: =SUMIFS(物件データ!$M$5:$M$180,物件データ!$L$5:$L$180,1,物件データ!$B$5:$B$180,$A43,物件データ!$J$5:$J$180,D$33) -> 0 | E43: =SUMIFS(物件データ!$M$5:$M$180,物件データ!$L$5:$L$180,1,物件データ!$B$5:$B$180,$A43,物件データ!$J$5:$J$180,E$33) -> 0 | F43: =SUMIFS(物件データ!$M$5:$M$180,物件データ!$L$5:$L$180,1,物件データ!$B$5:$B$180,$A43,物件データ!$J$5:$J$180,F$33) -> 5600000 | G43: =SUMIFS(物件データ!$M$5:$M$180,物件データ!$L$5:$L$180,1,物件データ!$B$5:$B$180,$A43,物件データ!$J$5:$J$180,G$33) -> 0 | H43: =SUMIFS(物件データ!$M$5:$M$180,物件データ!$L$5:$L$180,1,物件データ!$B$5:$B$180,$A43,物件データ!$J$5:$J$180,"?*") -> 5600000
...

Sheet ③成約価格分布
A1: ③ 期ごとの平均成約価格と価格分布（5,000万円きざみ）
A2: =" 集計対象："&設定!B4&"／販売価格が空欄の物件は除外" -> 集計対象：全て／販売価格が空欄の物件は除外
A4: 指標 | B4: 10期 | C4: 11期 | D4: 12期 | E4: 13期 | F4: 14期 | G4: 15期 | H4: 全期
A5: 棟数（価格あり） | B5: =COUNTIFS(物件データ!$L$5:$L$180,1,物件データ!$J$5:$J$180,B$4,物件データ!$G$5:$G$180,">0") -> 30 | C5: =COUNTIFS(物件データ!$L$5:$L$180,1,物件データ!$J$5:$J$180,C$4,物件データ!$G$5:$G$180,">0") -> 32 | D5: =COUNTIFS(物件データ!$L$5:$L$180,1,物件データ!$J$5:$J$180,D$4,物件データ!$G$5:$G$180,">0") -> 6 | E5: =COUNTIFS(物件データ!$L$5:$L$180,1,物件データ!$J$5:$J$180,E$4,物件データ!$G$5:$G$180,">0") -> 33 | F5: =COUNTIFS(物件データ!$L$5:$L$180,1,物件データ!$J$5:$J$180,F$4,物件データ!$G$5:$G$180,">0") -> 27 | G5: =COUNTIFS(物件データ!$L$5:$L$180,1,物件データ!$J$5:$J$180,G$4,物件データ!$G$5:$G$180,">0") -> 6 | H5: =COUNTIFS(物件データ!$L$5:$L$180,1,物件データ!$J$5:$J$180,"?*",物件データ!$G$5:$G$180,">0") -> 134
A6: 平均成約価格（円） | B6: =IFERROR(AVERAGEIFS(物件データ!$G$5:$G$180,物件データ!$L$5:$L$180,1,物件データ!$J$5:$J$180,B$4,物件データ!$G$5:$G$180,">0"),"") -> 62316667 | C6: =IFERROR(AVERAGEIFS(物件データ!$G$5:$G$180,物件データ!$L$5:$L$180,1,物件データ!$J$5:$J$180,C$4,物件データ!$G$5:$G$180,">0"),"") -> 75364062 | D6: =IFERROR(AVERAGEIFS(物件データ!$G$5:$G$180,物件データ!$L$5:$L$180,1,物件データ!$J$5:$J$180,D$4,物件データ!$G$5:$G$180,">0"),"") -> 70516667 | E6: =IFERROR(AVERAGEIFS(物件データ!$G$5:$G$180,物件データ!$L$5:$L$180,1,物件データ!$J$5:$J$180,E$4,物件データ!$G$5:$G$180,">0"),"") -> 63806061 | F6: =IFERROR(AVERAGEIFS(物件データ!$G$5:$G$180,物件データ!$L$5:$L$180,1,物件データ!$J$5:$J$180,F$4,物件データ!$G$5:$G$180,">0"),"") -> 1.0648889e+08 | G6: =IFERROR(AVERAGEIFS(物件データ!$G$5:$G$180,物件データ!$L$5:$L$180,1,物件データ!$J$5:$J$180,G$4,物件データ!$G$5:$G$180,">0"),"") -> 71650000 | H6: =IFERROR(AVERAGEIFS(物件データ!$G$5:$G$180,物件データ!$L$5:$L$180,1,物件データ!$J$5:$J$180,"?*",物件データ!$G$5:$G$180,">0"),"") -> 75484701
A7: 最低価格（円） | B7: =IFERROR(1/(1/_xlfn.MINIFS(物件データ!$G$5:$G$180,物件データ!$L$5:$L$180,1,物件データ!$J$5:$J$180,B$4,物件データ!$G$5:$G$180,">0")),"") -> 25900000 | C7: =IFERROR(1/(1/_xlfn.MINIFS(物件データ!$G$5:$G$180,物件データ!$L$5:$L$180,1,物件データ!$J$5:$J$180,C$4,物件データ!$G$5:$G$180,">0")),"") -> 19500000 | D7: =IFERROR(1/(1/_xlfn.MINIFS(物件データ!$G$5:$G$180,物件データ!$L$5:$L$180,1,物件データ!$J$5:$J$180,D$4,物件データ!$G$5:$G$180,">0")),"") -> 44800000 | E7: =IFERROR(1/(1/_xlfn.MINIFS(物件データ!$G$5:$G$180,物件データ!$L$5:$L$180,1,物件データ!$J$5:$J$180,E$4,物件データ!$G$5:$G$180,">0")),"") -> 6800000 | F7: =IFERROR(1/(1/_xlfn.MINIFS(物件データ!$G$5:$G$180,物件データ!$L$5:$L$180,1,物件データ!$J$5:$J$180,F$4,物件データ!$G$5:$G$180,">0")),"") -> 12000000 | G7: =IFERROR(1/(1/_xlfn.MINIFS(物件データ!$G$5:$G$180,物件データ!$L$5:$L$180,1,物件データ!$J$5:$J$180,G$4,物件データ!$G$5:$G$180,">0")),"") -> 29800000 | H7: =IFERROR(1/(1/_xlfn.MINIFS(物件データ!$G$5:$G$180,物件データ!$L$5:$L$180,1,物件データ!$J$5:$J$180,"?*",物件データ!$G$5:$G$180,">0")),"") -> 6800000
A8: 最高価格（円） | B8: =IFERROR(1/(1/_xlfn.MAXIFS(物件データ!$G$5:$G$180,物件データ!$L$5:$L$180,1,物件データ!$J$5:$J$180,B$4,物件データ!$G$5:$G$180,">0")),"") -> 138000000 | C8: =IFERROR(1/(1/_xlfn.MAXIFS(物件データ!$G$5:$G$180,物件データ!$L$5:$L$180,1,物件データ!$J$5:$J$180,C$4,物件データ!$G$5:$G$180,">0")),"") -> 400000000 | D8: =IFERROR(1/(1/_xlfn.MAXIFS(物件データ!$G$5:$G$180,物件データ!$L$5:$L$180,1,物件データ!$J$5:$J$180,D$4,物件データ!$G$5:$G$180,">0")),"") -> 99800000 | E8: =IFERROR(1/(1/_xlfn.MAXIFS(物件データ!$G$5:$G$180,物件データ!$L$5:$L$180,1,物件データ!$J$5:$J$180,E$4,物件データ!$G$5:$G$180,">0")),"") -> 320000000 | F8: =IFERROR(1/(1/_xlfn.MAXIFS(物件データ!$G$5:$G$180,物件データ!$L$5:$L$180,1,物件データ!$J$5:$J$180,F$4,物件データ!$G$5:$G$180,">0")),"") -> 300000000 | G8: =IFERROR(1/(1/_xlfn.MAXIFS(物件データ!$G$5:$G$180,物件データ!$L$5:$L$180,1,物件データ!$J$5:$J$180,G$4,物件データ!$G$5:$G$180,">0")),"") -> 180000000 | H8: =IFERROR(1/(1/_xlfn.MAXIFS(物件データ!$G$5:$G$180,物件データ!$L$5:$L$180,1,物件データ!$J$5:$J$180,"?*",物件データ!$G$5:$G$180,">0")),"") -> 400000000
